Workbook

Sheet Notes
G1: PROJECT: | N1: PROJECT NO: | R1: COMPANY: | V1: DOCUMENT NUMBER:
G2: GREATER STELLA AREA DEVELOPMENT | N2: JU11805D | R2: ITHACA ENERGY | V2: FPF1-HC-007
G3: DOCUMENT TITLE: | R3: ORIGINATOR: | V3: REV: | Z3: DATE: | AD3: PAGE NO:
G4: Trunnion Calculation Ellipse Method | R4: Piping Stress | V4: A | Z4: 41243 | AD4: NOTES
A5: Ref | C5: Calculation | AF5: Rev
D7: This calculation method supplements the corporate trunnion calculation spreadsheet PEC-EN-VSS-L-3204 and is only to be used for the Greater Stella Area Development project.
D11: This calculation method uses the formula 3.26 from 'Design of Piping Systems' by M.W. Kellogg Company.
D14: Instead of using the circular cross-section of the trunnion to determine the area and length for the unit loading, this method uses the area and length of the ellipse at the intersection of the trunnion and the pipe surface.
D18: The following formulae were substituted into those in formula 3.26;-
G20: π·Rn² | H20: ≡ | I20: π·a·b
G22: 2π·Rn | H22: ≡ | I22: π·(a + b)·{1 + 3·[(a - b)/(a + b)]²/[10 + √(4 - 3·[(a - b)/(a + b)]²)]} | AD22: Note i)
E24: Where,
E26: For trunnions on straight pipe,
L28: Minor Radius, a | M28: = | N28: r
L29: Major Radius, b | M29: = | N29: R·sinˉ¹(r/R)
E31: For trunnions on straight pipe with reinforcement pads (width = W),
L33: Minor Radius, a | M33: = | N33: r + W
L34: Major Radius, b | M34: = | N34: R·sinˉ¹(r/R) + W
E36: For trunnions on elbows,
J38: Minor Radius, a | K38: = | L38: R·sinˉ¹(r/R)
J39: Major Radius, b | K39: = | L39: (RB + R)·{cosˉ¹[(RB + O - r)/(RB + R)] - cosˉ¹[(RB + O + r)/(RB + R)]}/2
T40: where | W40: RB | X40: = | Y40: Radius of Elbow C/L
W41: O | X41: = | Y41: Trunnion offset
D47: NOTES:
D48: i) | E48: Based upon Srinivasa Ramanujan's approximation of the circumference of an ellipse.
D49: ii) | E49: Reinforcement pads shall not be used on elbows.

Sheet Calculation
I1: PROJECT: | S1: PROJECT NO: | Y1: COMPANY: | AE1: DOCUMENT NUMBER:
I2: =Notes!G2 -> GREATER STELLA AREA DEVELOPMENT | S2: =Notes!N2 -> JU11805D | Y2: =Notes!R2 -> ITHACA ENERGY | AE2: =Notes!V2 -> FPF1-HC-007
I3: DOCUMENT TITLE: | Y3: ORIGINATOR: | AE3: REV: | AK3: DATE: | AQ3: PAGE NO:
I4: =Notes!G4 -> Trunnion Calculation Ellipse Method | Y4: =Notes!R4 -> Piping Stress | AE4: =Notes!V4 -> A | AK4: =Notes!Z4 -> 41243 | AQ4: =IF(COUNT(BE11:BE60)=0,"1 of 1",CB7&" of "&COUNT(BE11:BE60)) -> 1 of 1
A5: Ref | AD5: Calculation No. | AE5: FPF1-000-REV1 | AK5: Node No. | AU5: Rev
AR6: All dimensions are in mm, UNO
D7: Pipe Data | CB7: =IF(ISNA(MATCH(AQ5,BE11:BE60,0)),0,MATCH(AQ5,BE11:BE60,0)) -> 0
N8: Nominal Pipe Size, NPS | O8: = | P8: 8
N9: OD, D | O9: = | P9: =VLOOKUP(P8,'Pipe Schedules'!$A$7:$B$48,2) -> 219.07 | BE9: Node | BG9: NPS | BI9: Axial Axis | BL9: Long. Axis | BO9: Circum. Axis
N10: Radius, R | O10: = | P10: =P9/2 -> 109.535
N11: Pipe Thickness / Schedule | O11: = | P11: STD | BO11: =IF(OR(BI11="",BL11=""),"",IF(OR(AND(UPPER(BI11)="X",UPPER(BL11)="Y"),AND(UPPER(BI11)="Y",UPPER(BL11)="X")),"z",IF(OR(AND(UPPER(BI11)="X",UPPER(BL11)="Z"),AND(UPPER(BI11)="Z",UPPER(BL11)="X")),"y","x")))
N12: Wall Thk, tp | O12: = | P12: =INDEX('Pipe Schedules'!$C$7:$T$48,MATCH(P8,'Pipe Schedules'!$A$7:$A$48,0),MATCH(P11,'Pipe Schedules'!$C$6:$T$6,0)) -> 8.18 | BO12: =IF(OR(BI12="",BL12=""),"",IF(OR(AND(UPPER(BI12)="X",UPPER(BL12)="Y"),AND(UPPER(BI12)="Y",UPPER(BL12)="X")),"z",IF(OR(AND(UPPER(BI12)="X",UPPER(BL12)="Z"),AND(UPPER(BI12)="Z",UPPER(BL12)="X")),"y","x")))
N13: Corrosion Allowance, C | O13: = | P13: 0 | BO13: =IF(OR(BI13="",BL13=""),"",IF(OR(AND(UPPER(BI13)="X",UPPER(BL13)="Y"),AND(UPPER(BI13)="Y",UPPER(BL13)="X")),"z",IF(OR(AND(UPPER(BI13)="X",UPPER(BL13)="Z"),AND(UPPER(BI13)="Z",UPPER(BL13)="X")),"y","x")))
N14: Mill Tolerance, MTp | O14: = | P14: 0.125 | BO14: =IF(OR(BI14="",BL14=""),"",IF(OR(AND(UPPER(BI14)="X",UPPER(BL14)="Y"),AND(UPPER(BI14)="Y",UPPER(BL14)="X")),"z",IF(OR(AND(UPPER(BI14)="X",UPPER(BL14)="Z"),AND(UPPER(BI14)="Z",UPPER(BL14)="X")),"y","x")))
O15: = | P15: =P12*P14 -> 1.0225 | BO15: =IF(OR(BI15="",BL15=""),"",IF(OR(AND(UPPER(BI15)="X",UPPER(BL15)="Y"),AND(UPPER(BI15)="Y",UPPER(BL15)="X")),"z",IF(OR(AND(UPPER(BI15)="X",UPPER(BL15)="Z"),AND(UPPER(BI15)="Z",UPPER(BL15)="X")),"y","x")))
D16: Trunnion Data | BO16: =IF(OR(BI16="",BL16=""),"",IF(OR(AND(UPPER(BI16)="X",UPPER(BL16)="Y"),AND(UPPER(BI16)="Y",UPPER(BL16)="X")),"z",IF(OR(AND(UPPER(BI16)="X",UPPER(BL16)="Z"),AND(UPPER(BI16)="Z",UPPER(BL16)="X")),"y","x")))
N17: Trunnion Nominal Size | O17: = | P17: 6 | BO17: =IF(OR(BI17="",BL17=""),"",IF(OR(AND(UPPER(BI17)="X",UPPER(BL17)="Y"),AND(UPPER(BI17)="Y",UPPER(BL17)="X")),"z",IF(OR(AND(UPPER(BI17)="X",UPPER(BL17)="Z"),AND(UPPER(BI17)="Z",UPPER(BL17)="X")),"y","x")))
N18: OD, d | O18: = | P18: =VLOOKUP(P17,'Pipe Schedules'!$A$7:$B$48,2) -> 168.27 | BO18: =IF(OR(BI18="",BL18=""),"",IF(OR(AND(UPPER(BI18)="X",UPPER(BL18)="Y"),AND(UPPER(BI18)="Y",UPPER(BL18)="X")),"z",IF(OR(AND(UPPER(BI18)="X",UPPER(BL18)="Z"),AND(UPPER(BI18)="Z",UPPER(BL18)="X")),"y","x")))
N19: Radius, r | O19: = | P19: =P18/2 -> 84.135 | BO19: =IF(OR(BI19="",BL19=""),"",IF(OR(AND(UPPER(BI19)="X",UPPER(BL19)="Y"),AND(UPPER(BI19)="Y",UPPER(BL19)="X")),"z",IF(OR(AND(UPPER(BI19)="X",UPPER(BL19)="Z"),AND(UPPER(BI19)="Z",UPPER(BL19)="X")),"y","x")))
N20: Trunnion Thk / Schedule | O20: = | P20: STD | BO20: =IF(OR(BI20="",BL20=""),"",IF(OR(AND(UPPER(BI20)="X",UPPER(BL20)="Y"),AND(UPPER(BI20)="Y",UPPER(BL20)="X")),"z",IF(OR(AND(UPPER(BI20)="X",UPPER(BL20)="Z"),AND(UPPER(BI20)="Z",UPPER(BL20)="X")),"y","x")))
N21: Wall Thk, tt | O21: = | P21: =INDEX('Pipe Schedules'!$C$7:$T$48,MATCH(P17,'Pipe Schedules'!$A$7:$A$48,0),MATCH(P20,'Pipe Schedules'!$C$6:$T$6,0)) -> 7.11 | BO21: =IF(OR(BI21="",BL21=""),"",IF(OR(AND(UPPER(BI21)="X",UPPER(BL21)="Y"),AND(UPPER(BI21)="Y",UPPER(BL21)="X")),"z",IF(OR(AND(UPPER(BI21)="X",UPPER(BL21)="Z"),AND(UPPER(BI21)="Z",UPPER(BL21)="X")),"y","x")))
N22: ID, di | O22: = | P22: =P18-2*P21 -> 154.05 | BO22: =IF(OR(BI22="",BL22=""),"",IF(OR(AND(UPPER(BI22)="X",UPPER(BL22)="Y"),AND(UPPER(BI22)="Y",UPPER(BL22)="X")),"z",IF(OR(AND(UPPER(BI22)="X",UPPER(BL22)="Z"),AND(UPPER(BI22)="Z",UPPER(BL22)="X")),"y","x")))
N23: Moment Arm, L | O23: = | P23: 0 | BO23: =IF(OR(BI23="",BL23=""),"",IF(OR(AND(UPPER(BI23)="X",UPPER(BL23)="Y"),AND(UPPER(BI23)="Y",UPPER(BL23)="X")),"z",IF(OR(AND(UPPER(BI23)="X",UPPER(BL23)="Z"),AND(UPPER(BI23)="Z",UPPER(BL23)="X")),"y","x")))
N24: Trunnion offset, O | O24: = | P24: 0 | BO24: =IF(OR(BI24="",BL24=""),"",IF(OR(AND(UPPER(BI24)="X",UPPER(BL24)="Y"),AND(UPPER(BI24)="Y",UPPER(BL24)="X")),"z",IF(OR(AND(UPPER(BI24)="X",UPPER(BL24)="Z"),AND(UPPER(BI24)="Z",UPPER(BL24)="X")),"y","x"))) | CB24: Non-Ellipse
N25: Re-Pad Thickness, tr | O25: = | P25: 0 | BO25: =IF(OR(BI25="",BL25=""),"",IF(OR(AND(UPPER(BI25)="X",UPPER(BL25)="Y"),AND(UPPER(BI25)="Y",UPPER(BL25)="X")),"z",IF(OR(AND(UPPER(BI25)="X",UPPER(BL25)="Z"),AND(UPPER(BI25)="Z",UPPER(BL25)="X")),"y","x"))) | CB25: Straight Pipe
N26: Mill Tolerance, MTr | O26: = | P26: 0.125 | BO26: =IF(OR(BI26="",BL26=""),"",IF(OR(AND(UPPER(BI26)="X",UPPER(BL26)="Y"),AND(UPPER(BI26)="Y",UPPER(BL26)="X")),"z",IF(OR(AND(UPPER(BI26)="X",UPPER(BL26)="Z"),AND(UPPER(BI26)="Z",UPPER(BL26)="X")),"y","x"))) | CB26: Elbow
O27: = | P27: =P25*P26 -> 0 | BO27: =IF(OR(BI27="",BL27=""),"",IF(OR(AND(UPPER(BI27)="X",UPPER(BL27)="Y"),AND(UPPER(BI27)="Y",UPPER(BL27)="X")),"z",IF(OR(AND(UPPER(BI27)="X",UPPER(BL27)="Z"),AND(UPPER(BI27)="Z",UPPER(BL27)="X")),"y","x")))
N28: Re-Pad Width, W | O28: = | P28: 0 | BO28: =IF(OR(BI28="",BL28=""),"",IF(OR(AND(UPPER(BI28)="X",UPPER(BL28)="Y"),AND(UPPER(BI28)="Y",UPPER(BL28)="X")),"z",IF(OR(AND(UPPER(BI28)="X",UPPER(BL28)="Z"),AND(UPPER(BI28)="Z",UPPER(BL28)="X")),"y","x")))
D29: Line Data | BO29: =IF(OR(BI29="",BL29=""),"",IF(OR(AND(UPPER(BI29)="X",UPPER(BL29)="Y"),AND(UPPER(BI29)="Y",UPPER(BL29)="X")),"z",IF(OR(AND(UPPER(BI29)="X",UPPER(BL29)="Z"),AND(UPPER(BI29)="Z",UPPER(BL29)="X")),"y","x")))
N30: Design Temperature, T | O30: = | P30: 0 | S30: °C | BO30: =IF(OR(BI30="",BL30=""),"",IF(OR(AND(UPPER(BI30)="X",UPPER(BL30)="Y"),AND(UPPER(BI30)="Y",UPPER(BL30)="X")),"z",IF(OR(AND(UPPER(BI30)="X",UPPER(BL30)="Z"),AND(UPPER(BI30)="Z",UPPER(BL30)="X")),"y","x")))
N31: Design : Operating Pressure, P | O31: = | P31: 0 | S31: 0 | V31: barg | BO31: =IF(OR(BI31="",BL31=""),"",IF(OR(AND(UPPER(BI31)="X",UPPER(BL31)="Y"),AND(UPPER(BI31)="Y",UPPER(BL31)="X")),"z",IF(OR(AND(UPPER(BI31)="X",UPPER(BL31)="Z"),AND(UPPER(BI31)="Z",UPPER(BL31)="X")),"y","x"))) | CC31: Other | CD31: 0
N32: Allowable Stress, Sh | O32: = | P32: 0 | S32: MPa | BO32: =IF(OR(BI32="",BL32=""),"",IF(OR(AND(UPPER(BI32)="X",UPPER(BL32)="Y"),AND(UPPER(BI32)="Y",UPPER(BL32)="X")),"z",IF(OR(AND(UPPER(BI32)="X",UPPER(BL32)="Z"),AND(UPPER(BI32)="Z",UPPER(BL32)="X")),"y","x"))) | CC32: 1D | CD32: 1
D33: Loading Data | BO33: =IF(OR(BI33="",BL33=""),"",IF(OR(AND(UPPER(BI33)="X",UPPER(BL33)="Y"),AND(UPPER(BI33)="Y",UPPER(BL33)="X")),"z",IF(OR(AND(UPPER(BI33)="X",UPPER(BL33)="Z"),AND(UPPER(BI33)="Z",UPPER(BL33)="X")),"y","x"))) | CC33: 1.5D | CD33: 1.5
N34: Attachment Type | O34: = | P34: Non-Ellipse | BO34: =IF(OR(BI34="",BL34=""),"",IF(OR(AND(UPPER(BI34)="X",UPPER(BL34)="Y"),AND(UPPER(BI34)="Y",UPPER(BL34)="X")),"z",IF(OR(AND(UPPER(BI34)="X",UPPER(BL34)="Z"),AND(UPPER(BI34)="Z",UPPER(BL34)="X")),"y","x"))) | CC34: 3D | CD34: 3
N35: Elbow Radius, RB | O35: = | P35: 1.5D | BO35: =IF(OR(BI35="",BL35=""),"",IF(OR(AND(UPPER(BI35)="X",UPPER(BL35)="Y"),AND(UPPER(BI35)="Y",UPPER(BL35)="X")),"z",IF(OR(AND(UPPER(BI35)="X",UPPER(BL35)="Z"),AND(UPPER(BI35)="Z",UPPER(BL35)="X")),"y","x"))) | CC35: 5D | CD35: 5
O36: = | P36: =VLOOKUP(P8,'Pipe Schedules'!$A$7:$U$48,21)*VLOOKUP(P35,Calculation!CC31:CD35,2,FALSE)*25.4 -> 304.8 | BO36: =IF(OR(BI36="",BL36=""),"",IF(OR(AND(UPPER(BI36)="X",UPPER(BL36)="Y"),AND(UPPER(BI36)="Y",UPPER(BL36)="X")),"z",IF(OR(AND(UPPER(BI36)="X",UPPER(BL36)="Z"),AND(UPPER(BI36)="Z",UPPER(BL36)="X")),"y","x")))
N37: Ellipse Minor Axes Radius, a | O37: = | P37: =IF(P34="Non-Ellipse",P19,IF(P34="Elbow",P10*ASIN(P19/P10),IF(P25>0,P19+P25,P19))) -> 84.135 | BO37: =IF(OR(BI37="",BL37=""),"",IF(OR(AND(UPPER(BI37)="X",UPPER(BL37)="Y"),AND(UPPER(BI37)="Y",UPPER(BL37)="X")),"z",IF(OR(AND(UPPER(BI37)="X",UPPER(BL37)="Z"),AND(UPPER(BI37)="Z",UPPER(BL37)="X")),"y","x")))
N38: Ellipse Major Axes Radius, b | O38: = | P38: =IF(P34="Non-Ellipse",P19,IF(P34="Elbow",(P36+P10)*(ACOS((P36+P24-P19)/(P36+P10))-ACOS((P36+P24+P19)/(P36+P10)))/2,IF(P25>0,P10*ASIN(P19/P10)+P25,P10*ASIN(P19/P10)))) -> 84.135 | BO38: =IF(OR(BI38="",BL38=""),"",IF(OR(AND(UPPER(BI38)="X",UPPER(BL38)="Y"),AND(UPPER(BI38)="Y",UPPER(BL38)="X")),"z",IF(OR(AND(UPPER(BI38)="X",UPPER(BL38)="Z"),AND(UPPER(BI38)="Z",UPPER(BL38)="X")),"y","x")))
N39: Attachment Area, AA | O39: = | P39: =PI()*P37*P38 -> 22238.386 | S39: mm² | BO39: =IF(OR(BI39="",BL39=""),"",IF(OR(AND(UPPER(BI39)="X",UPPER(BL39)="Y"),AND(UPPER(BI39)="Y",UPPER(BL39)="X")),"z",IF(OR(AND(UPPER(BI39)="X",UPPER(BL39)="Z"),AND(UPPER(BI39)="Z",UPPER(BL39)="X")),"y","x")))
N40: Attachment Circumference, CA | O40: = | P40: =IF(P34="Non-Ellipse",2*PI()*P37,PI()*(P37+P38)*(1+3*POWER((P37-P38)/(P37+P38),2)/(10+SQRT(4-3*POWER((P37-P38)/(P37+P38),2))))) -> 528.6358 | BO40: =IF(OR(BI40="",BL40=""),"",IF(OR(AND(UPPER(BI40)="X",UPPER(BL40)="Y"),AND(UPPER(BI40)="Y",UPPER(BL40)="X")),"z",IF(OR(AND(UPPER(BI40)="X",UPPER(BL40)="Z"),AND(UPPER(BI40)="Z",UPPER(BL40)="X")),"y","x")))
...

Sheet Case 1
B1: ELEMENT | C1: AXIAL | D1: SHEAR | E1: BENDING | F1: TORSION | G1: -----------Forces(N. | H1: )----------- | I1: ---------Moments(N.m. | J1: )------
B2: NODES: | C2: FORCE | D2: FORCE | E2: MOMENT | F2: MOMENT | G2: FX | H2: FY | I2: FZ | J2: MX | K2: MY | L2: MZ
B4: CASE | C4: =IF(P1="","","L"&MID(INDIRECT("P"&L4),6,2)) | D4: =IF(P1="","",MID(INDIRECT("P"&L4),SEARCH("(",INDIRECT("P"&L4),1)+1,3)) | E4: =IF(P1="","",MID(INDIRECT("P"&L4),SEARCH(")",INDIRECT("P"&L4),1)+2,LEN(INDIRECT("P"&L4)))) | L4: =IF(P1="","",MATCH("CASE*",P1:P10,0)) | M4: =ROUND(COUNT(P:P)*1.6,0) -> 0
B6: =IF(Calculation!BE11="","",Calculation!BE11) | C6: =IF($M$4=0,"",VLOOKUP($B6,INDIRECT("$P$1:$Z$"&$M$4),COLUMN()-1,0)) | D6: =IF($M$4=0,"",VLOOKUP($B6,INDIRECT("$P$1:$Z$"&$M$4),COLUMN()-1,0)) | E6: =IF($M$4=0,"",VLOOKUP($B6,INDIRECT("$P$1:$Z$"&$M$4),COLUMN()-1,0)) | F6: =IF($M$4=0,"",VLOOKUP($B6,INDIRECT("$P$1:$Z$"&$M$4),COLUMN()-1,0)) | G6: =IF($M$4=0,"",VLOOKUP($B6,INDIRECT("$P$1:$Z$"&$M$4),COLUMN()-1,0)) | H6: =IF($M$4=0,"",VLOOKUP($B6,INDIRECT("$P$1:$Z$"&$M$4),COLUMN()-1,0)) | I6: =IF($M$4=0,"",VLOOKUP($B6,INDIRECT("$P$1:$Z$"&$M$4),COLUMN()-1,0)) | J6: =IF($M$4=0,"",VLOOKUP($B6,INDIRECT("$P$1:$Z$"&$M$4),COLUMN()-1,0)) | ... L6: =IF($M$4=0,"",VLOOKUP($B6,INDIRECT("$P$1:$Z$"&$M$4),COLUMN()-1,0))
B7: =IF(Calculation!BE12="","",Calculation!BE12) | C7: =IF($M$4=0,"",VLOOKUP($B7,INDIRECT("$P$1:$Z$"&$M$4),COLUMN()-1,0)) | D7: =IF($M$4=0,"",VLOOKUP($B7,INDIRECT("$P$1:$Z$"&$M$4),COLUMN()-1,0)) | E7: =IF($M$4=0,"",VLOOKUP($B7,INDIRECT("$P$1:$Z$"&$M$4),COLUMN()-1,0)) | F7: =IF($M$4=0,"",VLOOKUP($B7,INDIRECT("$P$1:$Z$"&$M$4),COLUMN()-1,0)) | G7: =IF($M$4=0,"",VLOOKUP($B7,INDIRECT("$P$1:$Z$"&$M$4),COLUMN()-1,0)) | H7: =IF($M$4=0,"",VLOOKUP($B7,INDIRECT("$P$1:$Z$"&$M$4),COLUMN()-1,0)) | I7: =IF($M$4=0,"",VLOOKUP($B7,INDIRECT("$P$1:$Z$"&$M$4),COLUMN()-1,0)) | J7: =IF($M$4=0,"",VLOOKUP($B7,INDIRECT("$P$1:$Z$"&$M$4),COLUMN()-1,0)) | ... L7: =IF($M$4=0,"",VLOOKUP($B7,INDIRECT("$P$1:$Z$"&$M$4),COLUMN()-1,0))
B8: =IF(Calculation!BE13="","",Calculation!BE13) | C8: =IF($M$4=0,"",VLOOKUP($B8,INDIRECT("$P$1:$Z$"&$M$4),COLUMN()-1,0)) | D8: =IF($M$4=0,"",VLOOKUP($B8,INDIRECT("$P$1:$Z$"&$M$4),COLUMN()-1,0)) | E8: =IF($M$4=0,"",VLOOKUP($B8,INDIRECT("$P$1:$Z$"&$M$4),COLUMN()-1,0)) | F8: =IF($M$4=0,"",VLOOKUP($B8,INDIRECT("$P$1:$Z$"&$M$4),COLUMN()-1,0)) | G8: =IF($M$4=0,"",VLOOKUP($B8,INDIRECT("$P$1:$Z$"&$M$4),COLUMN()-1,0)) | H8: =IF($M$4=0,"",VLOOKUP($B8,INDIRECT("$P$1:$Z$"&$M$4),COLUMN()-1,0)) | I8: =IF($M$4=0,"",VLOOKUP($B8,INDIRECT("$P$1:$Z$"&$M$4),COLUMN()-1,0)) | J8: =IF($M$4=0,"",VLOOKUP($B8,INDIRECT("$P$1:$Z$"&$M$4),COLUMN()-1,0)) | ... L8: =IF($M$4=0,"",VLOOKUP($B8,INDIRECT("$P$1:$Z$"&$M$4),COLUMN()-1,0))
B9: =IF(Calculation!BE14="","",Calculation!BE14) | C9: =IF($M$4=0,"",VLOOKUP($B9,INDIRECT("$P$1:$Z$"&$M$4),COLUMN()-1,0)) | D9: =IF($M$4=0,"",VLOOKUP($B9,INDIRECT("$P$1:$Z$"&$M$4),COLUMN()-1,0)) | E9: =IF($M$4=0,"",VLOOKUP($B9,INDIRECT("$P$1:$Z$"&$M$4),COLUMN()-1,0)) | F9: =IF($M$4=0,"",VLOOKUP($B9,INDIRECT("$P$1:$Z$"&$M$4),COLUMN()-1,0)) | G9: =IF($M$4=0,"",VLOOKUP($B9,INDIRECT("$P$1:$Z$"&$M$4),COLUMN()-1,0)) | H9: =IF($M$4=0,"",VLOOKUP($B9,INDIRECT("$P$1:$Z$"&$M$4),COLUMN()-1,0)) | I9: =IF($M$4=0,"",VLOOKUP($B9,INDIRECT("$P$1:$Z$"&$M$4),COLUMN()-1,0)) | J9: =IF($M$4=0,"",VLOOKUP($B9,INDIRECT("$P$1:$Z$"&$M$4),COLUMN()-1,0)) | ... L9: =IF($M$4=0,"",VLOOKUP($B9,INDIRECT("$P$1:$Z$"&$M$4),COLUMN()-1,0))
B10: =IF(Calculation!BE15="","",Calculation!BE15) | C10: =IF($M$4=0,"",VLOOKUP($B10,INDIRECT("$P$1:$Z$"&$M$4),COLUMN()-1,0)) | D10: =IF($M$4=0,"",VLOOKUP($B10,INDIRECT("$P$1:$Z$"&$M$4),COLUMN()-1,0)) | E10: =IF($M$4=0,"",VLOOKUP($B10,INDIRECT("$P$1:$Z$"&$M$4),COLUMN()-1,0)) | F10: =IF($M$4=0,"",VLOOKUP($B10,INDIRECT("$P$1:$Z$"&$M$4),COLUMN()-1,0)) | G10: =IF($M$4=0,"",VLOOKUP($B10,INDIRECT("$P$1:$Z$"&$M$4),COLUMN()-1,0)) | H10: =IF($M$4=0,"",VLOOKUP($B10,INDIRECT("$P$1:$Z$"&$M$4),COLUMN()-1,0)) | I10: =IF($M$4=0,"",VLOOKUP($B10,INDIRECT("$P$1:$Z$"&$M$4),COLUMN()-1,0)) | J10: =IF($M$4=0,"",VLOOKUP($B10,INDIRECT("$P$1:$Z$"&$M$4),COLUMN()-1,0)) | ... L10: =IF($M$4=0,"",VLOOKUP($B10,INDIRECT("$P$1:$Z$"&$M$4),COLUMN()-1,0))
B11: =IF(Calculation!BE16="","",Calculation!BE16) | C11: =IF($M$4=0,"",VLOOKUP($B11,INDIRECT("$P$1:$Z$"&$M$4),COLUMN()-1,0)) | D11: =IF($M$4=0,"",VLOOKUP($B11,INDIRECT("$P$1:$Z$"&$M$4),COLUMN()-1,0)) | E11: =IF($M$4=0,"",VLOOKUP($B11,INDIRECT("$P$1:$Z$"&$M$4),COLUMN()-1,0)) | F11: =IF($M$4=0,"",VLOOKUP($B11,INDIRECT("$P$1:$Z$"&$M$4),COLUMN()-1,0)) | G11: =IF($M$4=0,"",VLOOKUP($B11,INDIRECT("$P$1:$Z$"&$M$4),COLUMN()-1,0)) | H11: =IF($M$4=0,"",VLOOKUP($B11,INDIRECT("$P$1:$Z$"&$M$4),COLUMN()-1,0)) | I11: =IF($M$4=0,"",VLOOKUP($B11,INDIRECT("$P$1:$Z$"&$M$4),COLUMN()-1,0)) | J11: =IF($M$4=0,"",VLOOKUP($B11,INDIRECT("$P$1:$Z$"&$M$4),COLUMN()-1,0)) | ... L11: =IF($M$4=0,"",VLOOKUP($B11,INDIRECT("$P$1:$Z$"&$M$4),COLUMN()-1,0))
B12: =IF(Calculation!BE17="","",Calculation!BE17) | C12: =IF($M$4=0,"",VLOOKUP($B12,INDIRECT("$P$1:$Z$"&$M$4),COLUMN()-1,0)) | D12: =IF($M$4=0,"",VLOOKUP($B12,INDIRECT("$P$1:$Z$"&$M$4),COLUMN()-1,0)) | E12: =IF($M$4=0,"",VLOOKUP($B12,INDIRECT("$P$1:$Z$"&$M$4),COLUMN()-1,0)) | F12: =IF($M$4=0,"",VLOOKUP($B12,INDIRECT("$P$1:$Z$"&$M$4),COLUMN()-1,0)) | G12: =IF($M$4=0,"",VLOOKUP($B12,INDIRECT("$P$1:$Z$"&$M$4),COLUMN()-1,0)) | H12: =IF($M$4=0,"",VLOOKUP($B12,INDIRECT("$P$1:$Z$"&$M$4),COLUMN()-1,0)) | I12: =IF($M$4=0,"",VLOOKUP($B12,INDIRECT("$P$1:$Z$"&$M$4),COLUMN()-1,0)) | J12: =IF($M$4=0,"",VLOOKUP($B12,INDIRECT("$P$1:$Z$"&$M$4),COLUMN()-1,0)) | ... L12: =IF($M$4=0,"",VLOOKUP($B12,INDIRECT("$P$1:$Z$"&$M$4),COLUMN()-1,0))
B13: =IF(Calculation!BE18="","",Calculation!BE18) | C13: =IF($M$4=0,"",VLOOKUP($B13,INDIRECT("$P$1:$Z$"&$M$4),COLUMN()-1,0)) | D13: =IF($M$4=0,"",VLOOKUP($B13,INDIRECT("$P$1:$Z$"&$M$4),COLUMN()-1,0)) | E13: =IF($M$4=0,"",VLOOKUP($B13,INDIRECT("$P$1:$Z$"&$M$4),COLUMN()-1,0)) | F13: =IF($M$4=0,"",VLOOKUP($B13,INDIRECT("$P$1:$Z$"&$M$4),COLUMN()-1,0)) | G13: =IF($M$4=0,"",VLOOKUP($B13,INDIRECT("$P$1:$Z$"&$M$4),COLUMN()-1,0)) | H13: =IF($M$4=0,"",VLOOKUP($B13,INDIRECT("$P$1:$Z$"&$M$4),COLUMN()-1,0)) | I13: =IF($M$4=0,"",VLOOKUP($B13,INDIRECT("$P$1:$Z$"&$M$4),COLUMN()-1,0)) | J13: =IF($M$4=0,"",VLOOKUP($B13,INDIRECT("$P$1:$Z$"&$M$4),COLUMN()-1,0)) | ... L13: =IF($M$4=0,"",VLOOKUP($B13,INDIRECT("$P$1:$Z$"&$M$4),COLUMN()-1,0))
B14: =IF(Calculation!BE19="","",Calculation!BE19) | C14: =IF($M$4=0,"",VLOOKUP($B14,INDIRECT("$P$1:$Z$"&$M$4),COLUMN()-1,0)) | D14: =IF($M$4=0,"",VLOOKUP($B14,INDIRECT("$P$1:$Z$"&$M$4),COLUMN()-1,0)) | E14: =IF($M$4=0,"",VLOOKUP($B14,INDIRECT("$P$1:$Z$"&$M$4),COLUMN()-1,0)) | F14: =IF($M$4=0,"",VLOOKUP($B14,INDIRECT("$P$1:$Z$"&$M$4),COLUMN()-1,0)) | G14: =IF($M$4=0,"",VLOOKUP($B14,INDIRECT("$P$1:$Z$"&$M$4),COLUMN()-1,0)) | H14: =IF($M$4=0,"",VLOOKUP($B14,INDIRECT("$P$1:$Z$"&$M$4),COLUMN()-1,0)) | I14: =IF($M$4=0,"",VLOOKUP($B14,INDIRECT("$P$1:$Z$"&$M$4),COLUMN()-1,0)) | J14: =IF($M$4=0,"",VLOOKUP($B14,INDIRECT("$P$1:$Z$"&$M$4),COLUMN()-1,0)) | ... L14: =IF($M$4=0,"",VLOOKUP($B14,INDIRECT("$P$1:$Z$"&$M$4),COLUMN()-1,0))
B15: =IF(Calculation!BE20="","",Calculation!BE20) | C15: =IF($M$4=0,"",VLOOKUP($B15,INDIRECT("$P$1:$Z$"&$M$4),COLUMN()-1,0)) | D15: =IF($M$4=0,"",VLOOKUP($B15,INDIRECT("$P$1:$Z$"&$M$4),COLUMN()-1,0)) | E15: =IF($M$4=0,"",VLOOKUP($B15,INDIRECT("$P$1:$Z$"&$M$4),COLUMN()-1,0)) | F15: =IF($M$4=0,"",VLOOKUP($B15,INDIRECT("$P$1:$Z$"&$M$4),COLUMN()-1,0)) | G15: =IF($M$4=0,"",VLOOKUP($B15,INDIRECT("$P$1:$Z$"&$M$4),COLUMN()-1,0)) | H15: =IF($M$4=0,"",VLOOKUP($B15,INDIRECT("$P$1:$Z$"&$M$4),COLUMN()-1,0)) | I15: =IF($M$4=0,"",VLOOKUP($B15,INDIRECT("$P$1:$Z$"&$M$4),COLUMN()-1,0)) | J15: =IF($M$4=0,"",VLOOKUP($B15,INDIRECT("$P$1:$Z$"&$M$4),COLUMN()-1,0)) | ... L15: =IF($M$4=0,"",VLOOKUP($B15,INDIRECT("$P$1:$Z$"&$M$4),COLUMN()-1,0))
B16: =IF(Calculation!BE21="","",Calculation!BE21) | C16: =IF($M$4=0,"",VLOOKUP($B16,INDIRECT("$P$1:$Z$"&$M$4),COLUMN()-1,0)) | D16: =IF($M$4=0,"",VLOOKUP($B16,INDIRECT("$P$1:$Z$"&$M$4),COLUMN()-1,0)) | E16: =IF($M$4=0,"",VLOOKUP($B16,INDIRECT("$P$1:$Z$"&$M$4),COLUMN()-1,0)) | F16: =IF($M$4=0,"",VLOOKUP($B16,INDIRECT("$P$1:$Z$"&$M$4),COLUMN()-1,0)) | G16: =IF($M$4=0,"",VLOOKUP($B16,INDIRECT("$P$1:$Z$"&$M$4),COLUMN()-1,0)) | H16: =IF($M$4=0,"",VLOOKUP($B16,INDIRECT("$P$1:$Z$"&$M$4),COLUMN()-1,0)) | I16: =IF($M$4=0,"",VLOOKUP($B16,INDIRECT("$P$1:$Z$"&$M$4),COLUMN()-1,0)) | J16: =IF($M$4=0,"",VLOOKUP($B16,INDIRECT("$P$1:$Z$"&$M$4),COLUMN()-1,0)) | ... L16: =IF($M$4=0,"",VLOOKUP($B16,INDIRECT("$P$1:$Z$"&$M$4),COLUMN()-1,0))
B17: =IF(Calculation!BE22="","",Calculation!BE22) | C17: =IF($M$4=0,"",VLOOKUP($B17,INDIRECT("$P$1:$Z$"&$M$4),COLUMN()-1,0)) | D17: =IF($M$4=0,"",VLOOKUP($B17,INDIRECT("$P$1:$Z$"&$M$4),COLUMN()-1,0)) | E17: =IF($M$4=0,"",VLOOKUP($B17,INDIRECT("$P$1:$Z$"&$M$4),COLUMN()-1,0)) | F17: =IF($M$4=0,"",VLOOKUP($B17,INDIRECT("$P$1:$Z$"&$M$4),COLUMN()-1,0)) | G17: =IF($M$4=0,"",VLOOKUP($B17,INDIRECT("$P$1:$Z$"&$M$4),COLUMN()-1,0)) | H17: =IF($M$4=0,"",VLOOKUP($B17,INDIRECT("$P$1:$Z$"&$M$4),COLUMN()-1,0)) | I17: =IF($M$4=0,"",VLOOKUP($B17,INDIRECT("$P$1:$Z$"&$M$4),COLUMN()-1,0)) | J17: =IF($M$4=0,"",VLOOKUP($B17,INDIRECT("$P$1:$Z$"&$M$4),COLUMN()-1,0)) | ... L17: =IF($M$4=0,"",VLOOKUP($B17,INDIRECT("$P$1:$Z$"&$M$4),COLUMN()-1,0))
... B40: =IF(Calculation!BE45="","",Calculation!BE45) | C40: =IF($M$4=0,"",VLOOKUP($B40,INDIRECT("$P$1:$Z$"&$M$4),COLUMN()-1,0)) | D40: =IF($M$4=0,"",VLOOKUP($B40,INDIRECT("$P$1:$Z$"&$M$4),COLUMN()-1,0)) | E40: =IF($M$4=0,"",VLOOKUP($B40,INDIRECT("$P$1:$Z$"&$M$4),COLUMN()-1,0)) | F40: =IF($M$4=0,"",VLOOKUP($B40,INDIRECT("$P$1:$Z$"&$M$4),COLUMN()-1,0)) | G40: =IF($M$4=0,"",VLOOKUP($B40,INDIRECT("$P$1:$Z$"&$M$4),COLUMN()-1,0)) | H40: =IF($M$4=0,"",VLOOKUP($B40,INDIRECT("$P$1:$Z$"&$M$4),COLUMN()-1,0)) | I40: =IF($M$4=0,"",VLOOKUP($B40,INDIRECT("$P$1:$Z$"&$M$4),COLUMN()-1,0)) | J40: =IF($M$4=0,"",VLOOKUP($B40,INDIRECT("$P$1:$Z$"&$M$4),COLUMN()-1,0)) | ... L40: =IF($M$4=0,"",VLOOKUP($B40,INDIRECT("$P$1:$Z$"&$M$4),COLUMN()-1,0))
B41: =IF(Calculation!BE47="","",Calculation!BE47) | C41: =IF($M$4=0,"",VLOOKUP($B41,INDIRECT("$P$1:$Z$"&$M$4),COLUMN()-1,0)) | D41: =IF($M$4=0,"",VLOOKUP($B41,INDIRECT("$P$1:$Z$"&$M$4),COLUMN()-1,0)) | E41: =IF($M$4=0,"",VLOOKUP($B41,INDIRECT("$P$1:$Z$"&$M$4),COLUMN()-1,0)) | F41: =IF($M$4=0,"",VLOOKUP($B41,INDIRECT("$P$1:$Z$"&$M$4),COLUMN()-1,0)) | G41: =IF($M$4=0,"",VLOOKUP($B41,INDIRECT("$P$1:$Z$"&$M$4),COLUMN()-1,0)) | H41: =IF($M$4=0,"",VLOOKUP($B41,INDIRECT("$P$1:$Z$"&$M$4),COLUMN()-1,0)) | I41: =IF($M$4=0,"",VLOOKUP($B41,INDIRECT("$P$1:$Z$"&$M$4),COLUMN()-1,0)) | J41: =IF($M$4=0,"",VLOOKUP($B41,INDIRECT("$P$1:$Z$"&$M$4),COLUMN()-1,0)) | ... L41: =IF($M$4=0,"",VLOOKUP($B41,INDIRECT("$P$1:$Z$"&$M$4),COLUMN()-1,0))
B42: =IF(Calculation!BE48="","",Calculation!BE48) | C42: =IF($M$4=0,"",VLOOKUP($B42,INDIRECT("$P$1:$Z$"&$M$4),COLUMN()-1,0)) | D42: =IF($M$4=0,"",VLOOKUP($B42,INDIRECT("$P$1:$Z$"&$M$4),COLUMN()-1,0)) | E42: =IF($M$4=0,"",VLOOKUP($B42,INDIRECT("$P$1:$Z$"&$M$4),COLUMN()-1,0)) | F42: =IF($M$4=0,"",VLOOKUP($B42,INDIRECT("$P$1:$Z$"&$M$4),COLUMN()-1,0)) | G42: =IF($M$4=0,"",VLOOKUP($B42,INDIRECT("$P$1:$Z$"&$M$4),COLUMN()-1,0)) | H42: =IF($M$4=0,"",VLOOKUP($B42,INDIRECT("$P$1:$Z$"&$M$4),COLUMN()-1,0)) | I42: =IF($M$4=0,"",VLOOKUP($B42,INDIRECT("$P$1:$Z$"&$M$4),COLUMN()-1,0)) | J42: =IF($M$4=0,"",VLOOKUP($B42,INDIRECT("$P$1:$Z$"&$M$4),COLUMN()-1,0)) | ... L42: =IF($M$4=0,"",VLOOKUP($B42,INDIRECT("$P$1:$Z$"&$M$4),COLUMN()-1,0))
B43: =IF(Calculation!BE49="","",Calculation!BE49) | C43: =IF($M$4=0,"",VLOOKUP($B43,INDIRECT("$P$1:$Z$"&$M$4),COLUMN()-1,0)) | D43: =IF($M$4=0,"",VLOOKUP($B43,INDIRECT("$P$1:$Z$"&$M$4),COLUMN()-1,0)) | E43: =IF($M$4=0,"",VLOOKUP($B43,INDIRECT("$P$1:$Z$"&$M$4),COLUMN()-1,0)) | F43: =IF($M$4=0,"",VLOOKUP($B43,INDIRECT("$P$1:$Z$"&$M$4),COLUMN()-1,0)) | G43: =IF($M$4=0,"",VLOOKUP($B43,INDIRECT("$P$1:$Z$"&$M$4),COLUMN()-1,0)) | H43: =IF($M$4=0,"",VLOOKUP($B43,INDIRECT("$P$1:$Z$"&$M$4),COLUMN()-1,0)) | I43: =IF($M$4=0,"",VLOOKUP($B43,INDIRECT("$P$1:$Z$"&$M$4),COLUMN()-1,0)) | J43: =IF($M$4=0,"",VLOOKUP($B43,INDIRECT("$P$1:$Z$"&$M$4),COLUMN()-1,0)) | ... L43: =IF($M$4=0,"",VLOOKUP($B43,INDIRECT("$P$1:$Z$"&$M$4),COLUMN()-1,0))
B44: =IF(Calculation!BE50="","",Calculation!BE50) | C44: =IF($M$4=0,"",VLOOKUP($B44,INDIRECT("$P$1:$Z$"&$M$4),COLUMN()-1,0)) | D44: =IF($M$4=0,"",VLOOKUP($B44,INDIRECT("$P$1:$Z$"&$M$4),COLUMN()-1,0)) | E44: =IF($M$4=0,"",VLOOKUP($B44,INDIRECT("$P$1:$Z$"&$M$4),COLUMN()-1,0)) | F44: =IF($M$4=0,"",VLOOKUP($B44,INDIRECT("$P$1:$Z$"&$M$4),COLUMN()-1,0)) | G44: =IF($M$4=0,"",VLOOKUP($B44,INDIRECT("$P$1:$Z$"&$M$4),COLUMN()-1,0)) | H44: =IF($M$4=0,"",VLOOKUP($B44,INDIRECT("$P$1:$Z$"&$M$4),COLUMN()-1,0)) | I44: =IF($M$4=0,"",VLOOKUP($B44,INDIRECT("$P$1:$Z$"&$M$4),COLUMN()-1,0)) | J44: =IF($M$4=0,"",VLOOKUP($B44,INDIRECT("$P$1:$Z$"&$M$4),COLUMN()-1,0)) | ... L44: =IF($M$4=0,"",VLOOKUP($B44,INDIRECT("$P$1:$Z$"&$M$4),COLUMN()-1,0))
B45: =IF(Calculation!BE51="","",Calculation!BE51) | C45: =IF($M$4=0,"",VLOOKUP($B45,INDIRECT("$P$1:$Z$"&$M$4),COLUMN()-1,0)) | D45: =IF($M$4=0,"",VLOOKUP($B45,INDIRECT("$P$1:$Z$"&$M$4),COLUMN()-1,0)) | E45: =IF($M$4=0,"",VLOOKUP($B45,INDIRECT("$P$1:$Z$"&$M$4),COLUMN()-1,0)) | F45: =IF($M$4=0,"",VLOOKUP($B45,INDIRECT("$P$1:$Z$"&$M$4),COLUMN()-1,0)) | G45: =IF($M$4=0,"",VLOOKUP($B45,INDIRECT("$P$1:$Z$"&$M$4),COLUMN()-1,0)) | H45: =IF($M$4=0,"",VLOOKUP($B45,INDIRECT("$P$1:$Z$"&$M$4),COLUMN()-1,0)) | I45: =IF($M$4=0,"",VLOOKUP($B45,INDIRECT("$P$1:$Z$"&$M$4),COLUMN()-1,0)) | J45: =IF($M$4=0,"",VLOOKUP($B45,INDIRECT("$P$1:$Z$"&$M$4),COLUMN()-1,0)) | ... L45: =IF($M$4=0,"",VLOOKUP($B45,INDIRECT("$P$1:$Z$"&$M$4),COLUMN()-1,0))
B46: =IF(Calculation!BE52="","",Calculation!BE52) | C46: =IF($M$4=0,"",VLOOKUP($B46,INDIRECT("$P$1:$Z$"&$M$4),COLUMN()-1,0)) | D46: =IF($M$4=0,"",VLOOKUP($B46,INDIRECT("$P$1:$Z$"&$M$4),COLUMN()-1,0)) | E46: =IF($M$4=0,"",VLOOKUP($B46,INDIRECT("$P$1:$Z$"&$M$4),COLUMN()-1,0)) | F46: =IF($M$4=0,"",VLOOKUP($B46,INDIRECT("$P$1:$Z$"&$M$4),COLUMN()-1,0)) | G46: =IF($M$4=0,"",VLOOKUP($B46,INDIRECT("$P$1:$Z$"&$M$4),COLUMN()-1,0)) | H46: =IF($M$4=0,"",VLOOKUP($B46,INDIRECT("$P$1:$Z$"&$M$4),COLUMN()-1,0)) | I46: =IF($M$4=0,"",VLOOKUP($B46,INDIRECT("$P$1:$Z$"&$M$4),COLUMN()-1,0)) | J46: =IF($M$4=0,"",VLOOKUP($B46,INDIRECT("$P$1:$Z$"&$M$4),COLUMN()-1,0)) | ... L46: =IF($M$4=0,"",VLOOKUP($B46,INDIRECT("$P$1:$Z$"&$M$4),COLUMN()-1,0))
B47: =IF(Calculation!BE53="","",Calculation!BE53) | C47: =IF($M$4=0,"",VLOOKUP($B47,INDIRECT("$P$1:$Z$"&$M$4),COLUMN()-1,0)) | D47: =IF($M$4=0,"",VLOOKUP($B47,INDIRECT("$P$1:$Z$"&$M$4),COLUMN()-1,0)) | E47: =IF($M$4=0,"",VLOOKUP($B47,INDIRECT("$P$1:$Z$"&$M$4),COLUMN()-1,0)) | F47: =IF($M$4=0,"",VLOOKUP($B47,INDIRECT("$P$1:$Z$"&$M$4),COLUMN()-1,0)) | G47: =IF($M$4=0,"",VLOOKUP($B47,INDIRECT("$P$1:$Z$"&$M$4),COLUMN()-1,0)) | H47: =IF($M$4=0,"",VLOOKUP($B47,INDIRECT("$P$1:$Z$"&$M$4),COLUMN()-1,0)) | I47: =IF($M$4=0,"",VLOOKUP($B47,INDIRECT("$P$1:$Z$"&$M$4),COLUMN()-1,0)) | J47: =IF($M$4=0,"",VLOOKUP($B47,INDIRECT("$P$1:$Z$"&$M$4),COLUMN()-1,0)) | ... L47: =IF($M$4=0,"",VLOOKUP($B47,INDIRECT("$P$1:$Z$"&$M$4),COLUMN()-1,0))
B48: =IF(Calculation!BE54="","",Calculation!BE54) | C48: =IF($M$4=0,"",VLOOKUP($B48,INDIRECT("$P$1:$Z$"&$M$4),COLUMN()-1,0)) | D48: =IF($M$4=0,"",VLOOKUP($B48,INDIRECT("$P$1:$Z$"&$M$4),COLUMN()-1,0)) | E48: =IF($M$4=0,"",VLOOKUP($B48,INDIRECT("$P$1:$Z$"&$M$4),COLUMN()-1,0)) | F48: =IF($M$4=0,"",VLOOKUP($B48,INDIRECT("$P$1:$Z$"&$M$4),COLUMN()-1,0)) | G48: =IF($M$4=0,"",VLOOKUP($B48,INDIRECT("$P$1:$Z$"&$M$4),COLUMN()-1,0)) | H48: =IF($M$4=0,"",VLOOKUP($B48,INDIRECT("$P$1:$Z$"&$M$4),COLUMN()-1,0)) | I48: =IF($M$4=0,"",VLOOKUP($B48,INDIRECT("$P$1:$Z$"&$M$4),COLUMN()-1,0)) | J48: =IF($M$4=0,"",VLOOKUP($B48,INDIRECT("$P$1:$Z$"&$M$4),COLUMN()-1,0)) | ... L48: =IF($M$4=0,"",VLOOKUP($B48,INDIRECT("$P$1:$Z$"&$M$4),COLUMN()-1,0))
B49: =IF(Calculation!BE55="","",Calculation!BE55) | C49: =IF($M$4=0,"",VLOOKUP($B49,INDIRECT("$P$1:$Z$"&$M$4),COLUMN()-1,0)) | D49: =IF($M$4=0,"",VLOOKUP($B49,INDIRECT("$P$1:$Z$"&$M$4),COLUMN()-1,0)) | E49: =IF($M$4=0,"",VLOOKUP($B49,INDIRECT("$P$1:$Z$"&$M$4),COLUMN()-1,0)) | F49: =IF($M$4=0,"",VLOOKUP($B49,INDIRECT("$P$1:$Z$"&$M$4),COLUMN()-1,0)) | G49: =IF($M$4=0,"",VLOOKUP($B49,INDIRECT("$P$1:$Z$"&$M$4),COLUMN()-1,0)) | H49: =IF($M$4=0,"",VLOOKUP($B49,INDIRECT("$P$1:$Z$"&$M$4),COLUMN()-1,0)) | I49: =IF($M$4=0,"",VLOOKUP($B49,INDIRECT("$P$1:$Z$"&$M$4),COLUMN()-1,0)) | J49: =IF($M$4=0,"",VLOOKUP($B49,INDIRECT("$P$1:$Z$"&$M$4),COLUMN()-1,0)) | ... L49: =IF($M$4=0,"",VLOOKUP($B49,INDIRECT("$P$1:$Z$"&$M$4),COLUMN()-1,0))
B50: =IF(Calculation!BE56="","",Calculation!BE56) | C50: =IF($M$4=0,"",VLOOKUP($B50,INDIRECT("$P$1:$Z$"&$M$4),COLUMN()-1,0)) | D50: =IF($M$4=0,"",VLOOKUP($B50,INDIRECT("$P$1:$Z$"&$M$4),COLUMN()-1,0)) | E50: =IF($M$4=0,"",VLOOKUP($B50,INDIRECT("$P$1:$Z$"&$M$4),COLUMN()-1,0)) | F50: =IF($M$4=0,"",VLOOKUP($B50,INDIRECT("$P$1:$Z$"&$M$4),COLUMN()-1,0)) | G50: =IF($M$4=0,"",VLOOKUP($B50,INDIRECT("$P$1:$Z$"&$M$4),COLUMN()-1,0)) | H50: =IF($M$4=0,"",VLOOKUP($B50,INDIRECT("$P$1:$Z$"&$M$4),COLUMN()-1,0)) | I50: =IF($M$4=0,"",VLOOKUP($B50,INDIRECT("$P$1:$Z$"&$M$4),COLUMN()-1,0)) | J50: =IF($M$4=0,"",VLOOKUP($B50,INDIRECT("$P$1:$Z$"&$M$4),COLUMN()-1,0)) | ... L50: =IF($M$4=0,"",VLOOKUP($B50,INDIRECT("$P$1:$Z$"&$M$4),COLUMN()-1,0))
B51: =IF(Calculation!BE57="","",Calculation!BE57) | C51: =IF($M$4=0,"",VLOOKUP($B51,INDIRECT("$P$1:$Z$"&$M$4),COLUMN()-1,0)) | D51: =IF($M$4=0,"",VLOOKUP($B51,INDIRECT("$P$1:$Z$"&$M$4),COLUMN()-1,0)) | E51: =IF($M$4=0,"",VLOOKUP($B51,INDIRECT("$P$1:$Z$"&$M$4),COLUMN()-1,0)) | F51: =IF($M$4=0,"",VLOOKUP($B51,INDIRECT("$P$1:$Z$"&$M$4),COLUMN()-1,0)) | G51: =IF($M$4=0,"",VLOOKUP($B51,INDIRECT("$P$1:$Z$"&$M$4),COLUMN()-1,0)) | H51: =IF($M$4=0,"",VLOOKUP($B51,INDIRECT("$P$1:$Z$"&$M$4),COLUMN()-1,0)) | I51: =IF($M$4=0,"",VLOOKUP($B51,INDIRECT("$P$1:$Z$"&$M$4),COLUMN()-1,0)) | J51: =IF($M$4=0,"",VLOOKUP($B51,INDIRECT("$P$1:$Z$"&$M$4),COLUMN()-1,0)) | ... L51: =IF($M$4=0,"",VLOOKUP($B51,INDIRECT("$P$1:$Z$"&$M$4),COLUMN()-1,0))
B52: =IF(Calculation!BE58="","",Calculation!BE58) | C52: =IF($M$4=0,"",VLOOKUP($B52,INDIRECT("$P$1:$Z$"&$M$4),COLUMN()-1,0)) | D52: =IF($M$4=0,"",VLOOKUP($B52,INDIRECT("$P$1:$Z$"&$M$4),COLUMN()-1,0)) | E52: =IF($M$4=0,"",VLOOKUP($B52,INDIRECT("$P$1:$Z$"&$M$4),COLUMN()-1,0)) | F52: =IF($M$4=0,"",VLOOKUP($B52,INDIRECT("$P$1:$Z$"&$M$4),COLUMN()-1,0)) | G52: =IF($M$4=0,"",VLOOKUP($B52,INDIRECT("$P$1:$Z$"&$M$4),COLUMN()-1,0)) | H52: =IF($M$4=0,"",VLOOKUP($B52,INDIRECT("$P$1:$Z$"&$M$4),COLUMN()-1,0)) | I52: =IF($M$4=0,"",VLOOKUP($B52,INDIRECT("$P$1:$Z$"&$M$4),COLUMN()-1,0)) | J52: =IF($M$4=0,"",VLOOKUP($B52,INDIRECT("$P$1:$Z$"&$M$4),COLUMN()-1,0)) | ... L52: =IF($M$4=0,"",VLOOKUP($B52,INDIRECT("$P$1:$Z$"&$M$4),COLUMN()-1,0))
... B55: =IF(Calculation!BE61="","",Calculation!BE61) | C55: =IF($M$4=0,"",VLOOKUP($B55,INDIRECT("$P$1:$Z$"&$M$4),COLUMN()-1,0)) | D55: =IF($M$4=0,"",VLOOKUP($B55,INDIRECT("$P$1:$Z$"&$M$4),COLUMN()-1,0)) | E55: =IF($M$4=0,"",VLOOKUP($B55,INDIRECT("$P$1:$Z$"&$M$4),COLUMN()-1,0)) | F55: =IF($M$4=0,"",VLOOKUP($B55,INDIRECT("$P$1:$Z$"&$M$4),COLUMN()-1,0)) | G55: =IF($M$4=0,"",VLOOKUP($B55,INDIRECT("$P$1:$Z$"&$M$4),COLUMN()-1,0)) | H55: =IF($M$4=0,"",VLOOKUP($B55,INDIRECT("$P$1:$Z$"&$M$4),COLUMN()-1,0)) | I55: =IF($M$4=0,"",VLOOKUP($B55,INDIRECT("$P$1:$Z$"&$M$4),COLUMN()-1,0)) | J55: =IF($M$4=0,"",VLOOKUP($B55,INDIRECT("$P$1:$Z$"&$M$4),COLUMN()-1,0)) | ... L55: =IF($M$4=0,"",VLOOKUP($B55,INDIRECT("$P$1:$Z$"&$M$4),COLUMN()-1,0))

Sheet Case 2
B1: ELEMENT | C1: AXIAL | D1: SHEAR | E1: BENDING | F1: TORSION | G1: -----------Forces(N. | H1: )----------- | I1: ---------Moments(N.m. | J1: )------
B2: NODES: | C2: FORCE | D2: FORCE | E2: MOMENT | F2: MOMENT | G2: FX | H2: FY | I2: FZ | J2: MX | K2: MY | L2: MZ
B4: CASE | C4: =IF(P1="","","L"&MID(INDIRECT("P"&L4),6,2)) | D4: =IF(P1="","",MID(INDIRECT("P"&L4),SEARCH("(",INDIRECT("P"&L4),1)+1,3)) | E4: =IF(P1="","",MID(INDIRECT("P"&L4),SEARCH(")",INDIRECT("P"&L4),1)+2,LEN(INDIRECT("P"&L4)))) | L4: =IF(P1="","",MATCH("CASE*",P1:P10,0)) | M4: =ROUND(COUNT(P:P)*1.6,0) -> 0
B6: =IF(Calculation!BE11="","",Calculation!BE11) | C6: =IF($M$4=0,"",VLOOKUP($B6,INDIRECT("$P$1:$Z$"&$M$4),COLUMN()-1,0)) | D6: =IF($M$4=0,"",VLOOKUP($B6,INDIRECT("$P$1:$Z$"&$M$4),COLUMN()-1,0)) | E6: =IF($M$4=0,"",VLOOKUP($B6,INDIRECT("$P$1:$Z$"&$M$4),COLUMN()-1,0)) | F6: =IF($M$4=0,"",VLOOKUP($B6,INDIRECT("$P$1:$Z$"&$M$4),COLUMN()-1,0)) | G6: =IF($M$4=0,"",VLOOKUP($B6,INDIRECT("$P$1:$Z$"&$M$4),COLUMN()-1,0)) | H6: =IF($M$4=0,"",VLOOKUP($B6,INDIRECT("$P$1:$Z$"&$M$4),COLUMN()-1,0)) | I6: =IF($M$4=0,"",VLOOKUP($B6,INDIRECT("$P$1:$Z$"&$M$4),COLUMN()-1,0)) | J6: =IF($M$4=0,"",VLOOKUP($B6,INDIRECT("$P$1:$Z$"&$M$4),COLUMN()-1,0)) | ... L6: =IF($M$4=0,"",VLOOKUP($B6,INDIRECT("$P$1:$Z$"&$M$4),COLUMN()-1,0))
B7: =IF(Calculation!BE12="","",Calculation!BE12) | C7: =IF($M$4=0,"",VLOOKUP($B7,INDIRECT("$P$1:$Z$"&$M$4),COLUMN()-1,0)) | D7: =IF($M$4=0,"",VLOOKUP($B7,INDIRECT("$P$1:$Z$"&$M$4),COLUMN()-1,0)) | E7: =IF($M$4=0,"",VLOOKUP($B7,INDIRECT("$P$1:$Z$"&$M$4),COLUMN()-1,0)) | F7: =IF($M$4=0,"",VLOOKUP($B7,INDIRECT("$P$1:$Z$"&$M$4),COLUMN()-1,0)) | G7: =IF($M$4=0,"",VLOOKUP($B7,INDIRECT("$P$1:$Z$"&$M$4),COLUMN()-1,0)) | H7: =IF($M$4=0,"",VLOOKUP($B7,INDIRECT("$P$1:$Z$"&$M$4),COLUMN()-1,0)) | I7: =IF($M$4=0,"",VLOOKUP($B7,INDIRECT("$P$1:$Z$"&$M$4),COLUMN()-1,0)) | J7: =IF($M$4=0,"",VLOOKUP($B7,INDIRECT("$P$1:$Z$"&$M$4),COLUMN()-1,0)) | ... L7: =IF($M$4=0,"",VLOOKUP($B7,INDIRECT("$P$1:$Z$"&$M$4),COLUMN()-1,0))
B8: =IF(Calculation!BE13="","",Calculation!BE13) | C8: =IF($M$4=0,"",VLOOKUP($B8,INDIRECT("$P$1:$Z$"&$M$4),COLUMN()-1,0)) | D8: =IF($M$4=0,"",VLOOKUP($B8,INDIRECT("$P$1:$Z$"&$M$4),COLUMN()-1,0)) | E8: =IF($M$4=0,"",VLOOKUP($B8,INDIRECT("$P$1:$Z$"&$M$4),COLUMN()-1,0)) | F8: =IF($M$4=0,"",VLOOKUP($B8,INDIRECT("$P$1:$Z$"&$M$4),COLUMN()-1,0)) | G8: =IF($M$4=0,"",VLOOKUP($B8,INDIRECT("$P$1:$Z$"&$M$4),COLUMN()-1,0)) | H8: =IF($M$4=0,"",VLOOKUP($B8,INDIRECT("$P$1:$Z$"&$M$4),COLUMN()-1,0)) | I8: =IF($M$4=0,"",VLOOKUP($B8,INDIRECT("$P$1:$Z$"&$M$4),COLUMN()-1,0)) | J8: =IF($M$4=0,"",VLOOKUP($B8,INDIRECT("$P$1:$Z$"&$M$4),COLUMN()-1,0)) | ... L8: =IF($M$4=0,"",VLOOKUP($B8,INDIRECT("$P$1:$Z$"&$M$4),COLUMN()-1,0))
B9: =IF(Calculation!BE14="","",Calculation!BE14) | C9: =IF($M$4=0,"",VLOOKUP($B9,INDIRECT("$P$1:$Z$"&$M$4),COLUMN()-1,0)) | D9: =IF($M$4=0,"",VLOOKUP($B9,INDIRECT("$P$1:$Z$"&$M$4),COLUMN()-1,0)) | E9: =IF($M$4=0,"",VLOOKUP($B9,INDIRECT("$P$1:$Z$"&$M$4),COLUMN()-1,0)) | F9: =IF($M$4=0,"",VLOOKUP($B9,INDIRECT("$P$1:$Z$"&$M$4),COLUMN()-1,0)) | G9: =IF($M$4=0,"",VLOOKUP($B9,INDIRECT("$P$1:$Z$"&$M$4),COLUMN()-1,0)) | H9: =IF($M$4=0,"",VLOOKUP($B9,INDIRECT("$P$1:$Z$"&$M$4),COLUMN()-1,0)) | I9: =IF($M$4=0,"",VLOOKUP($B9,INDIRECT("$P$1:$Z$"&$M$4),COLUMN()-1,0)) | J9: =IF($M$4=0,"",VLOOKUP($B9,INDIRECT("$P$1:$Z$"&$M$4),COLUMN()-1,0)) | ... L9: =IF($M$4=0,"",VLOOKUP($B9,INDIRECT("$P$1:$Z$"&$M$4),COLUMN()-1,0))
B10: =IF(Calculation!BE15="","",Calculation!BE15) | C10: =IF($M$4=0,"",VLOOKUP($B10,INDIRECT("$P$1:$Z$"&$M$4),COLUMN()-1,0)) | D10: =IF($M$4=0,"",VLOOKUP($B10,INDIRECT("$P$1:$Z$"&$M$4),COLUMN()-1,0)) | E10: =IF($M$4=0,"",VLOOKUP($B10,INDIRECT("$P$1:$Z$"&$M$4),COLUMN()-1,0)) | F10: =IF($M$4=0,"",VLOOKUP($B10,INDIRECT("$P$1:$Z$"&$M$4),COLUMN()-1,0)) | G10: =IF($M$4=0,"",VLOOKUP($B10,INDIRECT("$P$1:$Z$"&$M$4),COLUMN()-1,0)) | H10: =IF($M$4=0,"",VLOOKUP($B10,INDIRECT("$P$1:$Z$"&$M$4),COLUMN()-1,0)) | I10: =IF($M$4=0,"",VLOOKUP($B10,INDIRECT("$P$1:$Z$"&$M$4),COLUMN()-1,0)) | J10: =IF($M$4=0,"",VLOOKUP($B10,INDIRECT("$P$1:$Z$"&$M$4),COLUMN()-1,0)) | ... L10: =IF($M$4=0,"",VLOOKUP($B10,INDIRECT("$P$1:$Z$"&$M$4),COLUMN()-1,0))
B11: =IF(Calculation!BE16="","",Calculation!BE16) | C11: =IF($M$4=0,"",VLOOKUP($B11,INDIRECT("$P$1:$Z$"&$M$4),COLUMN()-1,0)) | D11: =IF($M$4=0,"",VLOOKUP($B11,INDIRECT("$P$1:$Z$"&$M$4),COLUMN()-1,0)) | E11: =IF($M$4=0,"",VLOOKUP($B11,INDIRECT("$P$1:$Z$"&$M$4),COLUMN()-1,0)) | F11: =IF($M$4=0,"",VLOOKUP($B11,INDIRECT("$P$1:$Z$"&$M$4),COLUMN()-1,0)) | G11: =IF($M$4=0,"",VLOOKUP($B11,INDIRECT("$P$1:$Z$"&$M$4),COLUMN()-1,0)) | H11: =IF($M$4=0,"",VLOOKUP($B11,INDIRECT("$P$1:$Z$"&$M$4),COLUMN()-1,0)) | I11: =IF($M$4=0,"",VLOOKUP($B11,INDIRECT("$P$1:$Z$"&$M$4),COLUMN()-1,0)) | J11: =IF($M$4=0,"",VLOOKUP($B11,INDIRECT("$P$1:$Z$"&$M$4),COLUMN()-1,0)) | ... L11: =IF($M$4=0,"",VLOOKUP($B11,INDIRECT("$P$1:$Z$"&$M$4),COLUMN()-1,0))
B12: =IF(Calculation!BE17="","",Calculation!BE17) | C12: =IF($M$4=0,"",VLOOKUP($B12,INDIRECT("$P$1:$Z$"&$M$4),COLUMN()-1,0)) | D12: =IF($M$4=0,"",VLOOKUP($B12,INDIRECT("$P$1:$Z$"&$M$4),COLUMN()-1,0)) | E12: =IF($M$4=0,"",VLOOKUP($B12,INDIRECT("$P$1:$Z$"&$M$4),COLUMN()-1,0)) | F12: =IF($M$4=0,"",VLOOKUP($B12,INDIRECT("$P$1:$Z$"&$M$4),COLUMN()-1,0)) | G12: =IF($M$4=0,"",VLOOKUP($B12,INDIRECT("$P$1:$Z$"&$M$4),COLUMN()-1,0)) | H12: =IF($M$4=0,"",VLOOKUP($B12,INDIRECT("$P$1:$Z$"&$M$4),COLUMN()-1,0)) | I12: =IF($M$4=0,"",VLOOKUP($B12,INDIRECT("$P$1:$Z$"&$M$4),COLUMN()-1,0)) | J12: =IF($M$4=0,"",VLOOKUP($B12,INDIRECT("$P$1:$Z$"&$M$4),COLUMN()-1,0)) | ... L12: =IF($M$4=0,"",VLOOKUP($B12,INDIRECT("$P$1:$Z$"&$M$4),COLUMN()-1,0))
B13: =IF(Calculation!BE18="","",Calculation!BE18) | C13: =IF($M$4=0,"",VLOOKUP($B13,INDIRECT("$P$1:$Z$"&$M$4),COLUMN()-1,0)) | D13: =IF($M$4=0,"",VLOOKUP($B13,INDIRECT("$P$1:$Z$"&$M$4),COLUMN()-1,0)) | E13: =IF($M$4=0,"",VLOOKUP($B13,INDIRECT("$P$1:$Z$"&$M$4),COLUMN()-1,0)) | F13: =IF($M$4=0,"",VLOOKUP($B13,INDIRECT("$P$1:$Z$"&$M$4),COLUMN()-1,0)) | G13: =IF($M$4=0,"",VLOOKUP($B13,INDIRECT("$P$1:$Z$"&$M$4),COLUMN()-1,0)) | H13: =IF($M$4=0,"",VLOOKUP($B13,INDIRECT("$P$1:$Z$"&$M$4),COLUMN()-1,0)) | I13: =IF($M$4=0,"",VLOOKUP($B13,INDIRECT("$P$1:$Z$"&$M$4),COLUMN()-1,0)) | J13: =IF($M$4=0,"",VLOOKUP($B13,INDIRECT("$P$1:$Z$"&$M$4),COLUMN()-1,0)) | ... L13: =IF($M$4=0,"",VLOOKUP($B13,INDIRECT("$P$1:$Z$"&$M$4),COLUMN()-1,0))
B14: =IF(Calculation!BE19="","",Calculation!BE19) | C14: =IF($M$4=0,"",VLOOKUP($B14,INDIRECT("$P$1:$Z$"&$M$4),COLUMN()-1,0)) | D14: =IF($M$4=0,"",VLOOKUP($B14,INDIRECT("$P$1:$Z$"&$M$4),COLUMN()-1,0)) | E14: =IF($M$4=0,"",VLOOKUP($B14,INDIRECT("$P$1:$Z$"&$M$4),COLUMN()-1,0)) | F14: =IF($M$4=0,"",VLOOKUP($B14,INDIRECT("$P$1:$Z$"&$M$4),COLUMN()-1,0)) | G14: =IF($M$4=0,"",VLOOKUP($B14,INDIRECT("$P$1:$Z$"&$M$4),COLUMN()-1,0)) | H14: =IF($M$4=0,"",VLOOKUP($B14,INDIRECT("$P$1:$Z$"&$M$4),COLUMN()-1,0)) | I14: =IF($M$4=0,"",VLOOKUP($B14,INDIRECT("$P$1:$Z$"&$M$4),COLUMN()-1,0)) | J14: =IF($M$4=0,"",VLOOKUP($B14,INDIRECT("$P$1:$Z$"&$M$4),COLUMN()-1,0)) | ... L14: =IF($M$4=0,"",VLOOKUP($B14,INDIRECT("$P$1:$Z$"&$M$4),COLUMN()-1,0))
B15: =IF(Calculation!BE20="","",Calculation!BE20) | C15: =IF($M$4=0,"",VLOOKUP($B15,INDIRECT("$P$1:$Z$"&$M$4),COLUMN()-1,0)) | D15: =IF($M$4=0,"",VLOOKUP($B15,INDIRECT("$P$1:$Z$"&$M$4),COLUMN()-1,0)) | E15: =IF($M$4=0,"",VLOOKUP($B15,INDIRECT("$P$1:$Z$"&$M$4),COLUMN()-1,0)) | F15: =IF($M$4=0,"",VLOOKUP($B15,INDIRECT("$P$1:$Z$"&$M$4),COLUMN()-1,0)) | G15: =IF($M$4=0,"",VLOOKUP($B15,INDIRECT("$P$1:$Z$"&$M$4),COLUMN()-1,0)) | H15: =IF($M$4=0,"",VLOOKUP($B15,INDIRECT("$P$1:$Z$"&$M$4),COLUMN()-1,0)) | I15: =IF($M$4=0,"",VLOOKUP($B15,INDIRECT("$P$1:$Z$"&$M$4),COLUMN()-1,0)) | J15: =IF($M$4=0,"",VLOOKUP($B15,INDIRECT("$P$1:$Z$"&$M$4),COLUMN()-1,0)) | ... L15: =IF($M$4=0,"",VLOOKUP($B15,INDIRECT("$P$1:$Z$"&$M$4),COLUMN()-1,0))
B16: =IF(Calculation!BE21="","",Calculation!BE21) | C16: =IF($M$4=0,"",VLOOKUP($B16,INDIRECT("$P$1:$Z$"&$M$4),COLUMN()-1,0)) | D16: =IF($M$4=0,"",VLOOKUP($B16,INDIRECT("$P$1:$Z$"&$M$4),COLUMN()-1,0)) | E16: =IF($M$4=0,"",VLOOKUP($B16,INDIRECT("$P$1:$Z$"&$M$4),COLUMN()-1,0)) | F16: =IF($M$4=0,"",VLOOKUP($B16,INDIRECT("$P$1:$Z$"&$M$4),COLUMN()-1,0)) | G16: =IF($M$4=0,"",VLOOKUP($B16,INDIRECT("$P$1:$Z$"&$M$4),COLUMN()-1,0)) | H16: =IF($M$4=0,"",VLOOKUP($B16,INDIRECT("$P$1:$Z$"&$M$4),COLUMN()-1,0)) | I16: =IF($M$4=0,"",VLOOKUP($B16,INDIRECT("$P$1:$Z$"&$M$4),COLUMN()-1,0)) | J16: =IF($M$4=0,"",VLOOKUP($B16,INDIRECT("$P$1:$Z$"&$M$4),COLUMN()-1,0)) | ... L16: =IF($M$4=0,"",VLOOKUP($B16,INDIRECT("$P$1:$Z$"&$M$4),COLUMN()-1,0))
B17: =IF(Calculation!BE22="","",Calculation!BE22) | C17: =IF($M$4=0,"",VLOOKUP($B17,INDIRECT("$P$1:$Z$"&$M$4),COLUMN()-1,0)) | D17: =IF($M$4=0,"",VLOOKUP($B17,INDIRECT("$P$1:$Z$"&$M$4),COLUMN()-1,0)) | E17: =IF($M$4=0,"",VLOOKUP($B17,INDIRECT("$P$1:$Z$"&$M$4),COLUMN()-1,0)) | F17: =IF($M$4=0,"",VLOOKUP($B17,INDIRECT("$P$1:$Z$"&$M$4),COLUMN()-1,0)) | G17: =IF($M$4=0,"",VLOOKUP($B17,INDIRECT("$P$1:$Z$"&$M$4),COLUMN()-1,0)) | H17: =IF($M$4=0,"",VLOOKUP($B17,INDIRECT("$P$1:$Z$"&$M$4),COLUMN()-1,0)) | I17: =IF($M$4=0,"",VLOOKUP($B17,INDIRECT("$P$1:$Z$"&$M$4),COLUMN()-1,0)) | J17: =IF($M$4=0,"",VLOOKUP($B17,INDIRECT("$P$1:$Z$"&$M$4),COLUMN()-1,0)) | ... L17: =IF($M$4=0,"",VLOOKUP($B17,INDIRECT("$P$1:$Z$"&$M$4),COLUMN()-1,0))
... B40: =IF(Calculation!BE45="","",Calculation!BE45) | C40: =IF($M$4=0,"",VLOOKUP($B40,INDIRECT("$P$1:$Z$"&$M$4),COLUMN()-1,0)) | D40: =IF($M$4=0,"",VLOOKUP($B40,INDIRECT("$P$1:$Z$"&$M$4),COLUMN()-1,0)) | E40: =IF($M$4=0,"",VLOOKUP($B40,INDIRECT("$P$1:$Z$"&$M$4),COLUMN()-1,0)) | F40: =IF($M$4=0,"",VLOOKUP($B40,INDIRECT("$P$1:$Z$"&$M$4),COLUMN()-1,0)) | G40: =IF($M$4=0,"",VLOOKUP($B40,INDIRECT("$P$1:$Z$"&$M$4),COLUMN()-1,0)) | H40: =IF($M$4=0,"",VLOOKUP($B40,INDIRECT("$P$1:$Z$"&$M$4),COLUMN()-1,0)) | I40: =IF($M$4=0,"",VLOOKUP($B40,INDIRECT("$P$1:$Z$"&$M$4),COLUMN()-1,0)) | J40: =IF($M$4=0,"",VLOOKUP($B40,INDIRECT("$P$1:$Z$"&$M$4),COLUMN()-1,0)) | ... L40: =IF($M$4=0,"",VLOOKUP($B40,INDIRECT("$P$1:$Z$"&$M$4),COLUMN()-1,0))
B41: =IF(Calculation!BE47="","",Calculation!BE47) | C41: =IF($M$4=0,"",VLOOKUP($B41,INDIRECT("$P$1:$Z$"&$M$4),COLUMN()-1,0)) | D41: =IF($M$4=0,"",VLOOKUP($B41,INDIRECT("$P$1:$Z$"&$M$4),COLUMN()-1,0)) | E41: =IF($M$4=0,"",VLOOKUP($B41,INDIRECT("$P$1:$Z$"&$M$4),COLUMN()-1,0)) | F41: =IF($M$4=0,"",VLOOKUP($B41,INDIRECT("$P$1:$Z$"&$M$4),COLUMN()-1,0)) | G41: =IF($M$4=0,"",VLOOKUP($B41,INDIRECT("$P$1:$Z$"&$M$4),COLUMN()-1,0)) | H41: =IF($M$4=0,"",VLOOKUP($B41,INDIRECT("$P$1:$Z$"&$M$4),COLUMN()-1,0)) | I41: =IF($M$4=0,"",VLOOKUP($B41,INDIRECT("$P$1:$Z$"&$M$4),COLUMN()-1,0)) | J41: =IF($M$4=0,"",VLOOKUP($B41,INDIRECT("$P$1:$Z$"&$M$4),COLUMN()-1,0)) | ... L41: =IF($M$4=0,"",VLOOKUP($B41,INDIRECT("$P$1:$Z$"&$M$4),COLUMN()-1,0))
B42: =IF(Calculation!BE48="","",Calculation!BE48) | C42: =IF($M$4=0,"",VLOOKUP($B42,INDIRECT("$P$1:$Z$"&$M$4),COLUMN()-1,0)) | D42: =IF($M$4=0,"",VLOOKUP($B42,INDIRECT("$P$1:$Z$"&$M$4),COLUMN()-1,0)) | E42: =IF($M$4=0,"",VLOOKUP($B42,INDIRECT("$P$1:$Z$"&$M$4),COLUMN()-1,0)) | F42: =IF($M$4=0,"",VLOOKUP($B42,INDIRECT("$P$1:$Z$"&$M$4),COLUMN()-1,0)) | G42: =IF($M$4=0,"",VLOOKUP($B42,INDIRECT("$P$1:$Z$"&$M$4),COLUMN()-1,0)) | H42: =IF($M$4=0,"",VLOOKUP($B42,INDIRECT("$P$1:$Z$"&$M$4),COLUMN()-1,0)) | I42: =IF($M$4=0,"",VLOOKUP($B42,INDIRECT("$P$1:$Z$"&$M$4),COLUMN()-1,0)) | J42: =IF($M$4=0,"",VLOOKUP($B42,INDIRECT("$P$1:$Z$"&$M$4),COLUMN()-1,0)) | ... L42: =IF($M$4=0,"",VLOOKUP($B42,INDIRECT("$P$1:$Z$"&$M$4),COLUMN()-1,0))
B43: =IF(Calculation!BE49="","",Calculation!BE49) | C43: =IF($M$4=0,"",VLOOKUP($B43,INDIRECT("$P$1:$Z$"&$M$4),COLUMN()-1,0)) | D43: =IF($M$4=0,"",VLOOKUP($B43,INDIRECT("$P$1:$Z$"&$M$4),COLUMN()-1,0)) | E43: =IF($M$4=0,"",VLOOKUP($B43,INDIRECT("$P$1:$Z$"&$M$4),COLUMN()-1,0)) | F43: =IF($M$4=0,"",VLOOKUP($B43,INDIRECT("$P$1:$Z$"&$M$4),COLUMN()-1,0)) | G43: =IF($M$4=0,"",VLOOKUP($B43,INDIRECT("$P$1:$Z$"&$M$4),COLUMN()-1,0)) | H43: =IF($M$4=0,"",VLOOKUP($B43,INDIRECT("$P$1:$Z$"&$M$4),COLUMN()-1,0)) | I43: =IF($M$4=0,"",VLOOKUP($B43,INDIRECT("$P$1:$Z$"&$M$4),COLUMN()-1,0)) | J43: =IF($M$4=0,"",VLOOKUP($B43,INDIRECT("$P$1:$Z$"&$M$4),COLUMN()-1,0)) | ... L43: =IF($M$4=0,"",VLOOKUP($B43,INDIRECT("$P$1:$Z$"&$M$4),COLUMN()-1,0))
B44: =IF(Calculation!BE50="","",Calculation!BE50) | C44: =IF($M$4=0,"",VLOOKUP($B44,INDIRECT("$P$1:$Z$"&$M$4),COLUMN()-1,0)) | D44: =IF($M$4=0,"",VLOOKUP($B44,INDIRECT("$P$1:$Z$"&$M$4),COLUMN()-1,0)) | E44: =IF($M$4=0,"",VLOOKUP($B44,INDIRECT("$P$1:$Z$"&$M$4),COLUMN()-1,0)) | F44: =IF($M$4=0,"",VLOOKUP($B44,INDIRECT("$P$1:$Z$"&$M$4),COLUMN()-1,0)) | G44: =IF($M$4=0,"",VLOOKUP($B44,INDIRECT("$P$1:$Z$"&$M$4),COLUMN()-1,0)) | H44: =IF($M$4=0,"",VLOOKUP($B44,INDIRECT("$P$1:$Z$"&$M$4),COLUMN()-1,0)) | I44: =IF($M$4=0,"",VLOOKUP($B44,INDIRECT("$P$1:$Z$"&$M$4),COLUMN()-1,0)) | J44: =IF($M$4=0,"",VLOOKUP($B44,INDIRECT("$P$1:$Z$"&$M$4),COLUMN()-1,0)) | ... L44: =IF($M$4=0,"",VLOOKUP($B44,INDIRECT("$P$1:$Z$"&$M$4),COLUMN()-1,0))
B45: =IF(Calculation!BE51="","",Calculation!BE51) | C45: =IF($M$4=0,"",VLOOKUP($B45,INDIRECT("$P$1:$Z$"&$M$4),COLUMN()-1,0)) | D45: =IF($M$4=0,"",VLOOKUP($B45,INDIRECT("$P$1:$Z$"&$M$4),COLUMN()-1,0)) | E45: =IF($M$4=0,"",VLOOKUP($B45,INDIRECT("$P$1:$Z$"&$M$4),COLUMN()-1,0)) | F45: =IF($M$4=0,"",VLOOKUP($B45,INDIRECT("$P$1:$Z$"&$M$4),COLUMN()-1,0)) | G45: =IF($M$4=0,"",VLOOKUP($B45,INDIRECT("$P$1:$Z$"&$M$4),COLUMN()-1,0)) | H45: =IF($M$4=0,"",VLOOKUP($B45,INDIRECT("$P$1:$Z$"&$M$4),COLUMN()-1,0)) | I45: =IF($M$4=0,"",VLOOKUP($B45,INDIRECT("$P$1:$Z$"&$M$4),COLUMN()-1,0)) | J45: =IF($M$4=0,"",VLOOKUP($B45,INDIRECT("$P$1:$Z$"&$M$4),COLUMN()-1,0)) | ... L45: =IF($M$4=0,"",VLOOKUP($B45,INDIRECT("$P$1:$Z$"&$M$4),COLUMN()-1,0))
B46: =IF(Calculation!BE52="","",Calculation!BE52) | C46: =IF($M$4=0,"",VLOOKUP($B46,INDIRECT("$P$1:$Z$"&$M$4),COLUMN()-1,0)) | D46: =IF($M$4=0,"",VLOOKUP($B46,INDIRECT("$P$1:$Z$"&$M$4),COLUMN()-1,0)) | E46: =IF($M$4=0,"",VLOOKUP($B46,INDIRECT("$P$1:$Z$"&$M$4),COLUMN()-1,0)) | F46: =IF($M$4=0,"",VLOOKUP($B46,INDIRECT("$P$1:$Z$"&$M$4),COLUMN()-1,0)) | G46: =IF($M$4=0,"",VLOOKUP($B46,INDIRECT("$P$1:$Z$"&$M$4),COLUMN()-1,0)) | H46: =IF($M$4=0,"",VLOOKUP($B46,INDIRECT("$P$1:$Z$"&$M$4),COLUMN()-1,0)) | I46: =IF($M$4=0,"",VLOOKUP($B46,INDIRECT("$P$1:$Z$"&$M$4),COLUMN()-1,0)) | J46: =IF($M$4=0,"",VLOOKUP($B46,INDIRECT("$P$1:$Z$"&$M$4),COLUMN()-1,0)) | ... L46: =IF($M$4=0,"",VLOOKUP($B46,INDIRECT("$P$1:$Z$"&$M$4),COLUMN()-1,0))
B47: =IF(Calculation!BE53="","",Calculation!BE53) | C47: =IF($M$4=0,"",VLOOKUP($B47,INDIRECT("$P$1:$Z$"&$M$4),COLUMN()-1,0)) | D47: =IF($M$4=0,"",VLOOKUP($B47,INDIRECT("$P$1:$Z$"&$M$4),COLUMN()-1,0)) | E47: =IF($M$4=0,"",VLOOKUP($B47,INDIRECT("$P$1:$Z$"&$M$4),COLUMN()-1,0)) | F47: =IF($M$4=0,"",VLOOKUP($B47,INDIRECT("$P$1:$Z$"&$M$4),COLUMN()-1,0)) | G47: =IF($M$4=0,"",VLOOKUP($B47,INDIRECT("$P$1:$Z$"&$M$4),COLUMN()-1,0)) | H47: =IF($M$4=0,"",VLOOKUP($B47,INDIRECT("$P$1:$Z$"&$M$4),COLUMN()-1,0)) | I47: =IF($M$4=0,"",VLOOKUP($B47,INDIRECT("$P$1:$Z$"&$M$4),COLUMN()-1,0)) | J47: =IF($M$4=0,"",VLOOKUP($B47,INDIRECT("$P$1:$Z$"&$M$4),COLUMN()-1,0)) | ... L47: =IF($M$4=0,"",VLOOKUP($B47,INDIRECT("$P$1:$Z$"&$M$4),COLUMN()-1,0))
B48: =IF(Calculation!BE54="","",Calculation!BE54) | C48: =IF($M$4=0,"",VLOOKUP($B48,INDIRECT("$P$1:$Z$"&$M$4),COLUMN()-1,0)) | D48: =IF($M$4=0,"",VLOOKUP($B48,INDIRECT("$P$1:$Z$"&$M$4),COLUMN()-1,0)) | E48: =IF($M$4=0,"",VLOOKUP($B48,INDIRECT("$P$1:$Z$"&$M$4),COLUMN()-1,0)) | F48: =IF($M$4=0,"",VLOOKUP($B48,INDIRECT("$P$1:$Z$"&$M$4),COLUMN()-1,0)) | G48: =IF($M$4=0,"",VLOOKUP($B48,INDIRECT("$P$1:$Z$"&$M$4),COLUMN()-1,0)) | H48: =IF($M$4=0,"",VLOOKUP($B48,INDIRECT("$P$1:$Z$"&$M$4),COLUMN()-1,0)) | I48: =IF($M$4=0,"",VLOOKUP($B48,INDIRECT("$P$1:$Z$"&$M$4),COLUMN()-1,0)) | J48: =IF($M$4=0,"",VLOOKUP($B48,INDIRECT("$P$1:$Z$"&$M$4),COLUMN()-1,0)) | ... L48: =IF($M$4=0,"",VLOOKUP($B48,INDIRECT("$P$1:$Z$"&$M$4),COLUMN()-1,0))
B49: =IF(Calculation!BE55="","",Calculation!BE55) | C49: =IF($M$4=0,"",VLOOKUP($B49,INDIRECT("$P$1:$Z$"&$M$4),COLUMN()-1,0)) | D49: =IF($M$4=0,"",VLOOKUP($B49,INDIRECT("$P$1:$Z$"&$M$4),COLUMN()-1,0)) | E49: =IF($M$4=0,"",VLOOKUP($B49,INDIRECT("$P$1:$Z$"&$M$4),COLUMN()-1,0)) | F49: =IF($M$4=0,"",VLOOKUP($B49,INDIRECT("$P$1:$Z$"&$M$4),COLUMN()-1,0)) | G49: =IF($M$4=0,"",VLOOKUP($B49,INDIRECT("$P$1:$Z$"&$M$4),COLUMN()-1,0)) | H49: =IF($M$4=0,"",VLOOKUP($B49,INDIRECT("$P$1:$Z$"&$M$4),COLUMN()-1,0)) | I49: =IF($M$4=0,"",VLOOKUP($B49,INDIRECT("$P$1:$Z$"&$M$4),COLUMN()-1,0)) | J49: =IF($M$4=0,"",VLOOKUP($B49,INDIRECT("$P$1:$Z$"&$M$4),COLUMN()-1,0)) | ... L49: =IF($M$4=0,"",VLOOKUP($B49,INDIRECT("$P$1:$Z$"&$M$4),COLUMN()-1,0))
B50: =IF(Calculation!BE56="","",Calculation!BE56) | C50: =IF($M$4=0,"",VLOOKUP($B50,INDIRECT("$P$1:$Z$"&$M$4),COLUMN()-1,0)) | D50: =IF($M$4=0,"",VLOOKUP($B50,INDIRECT("$P$1:$Z$"&$M$4),COLUMN()-1,0)) | E50: =IF($M$4=0,"",VLOOKUP($B50,INDIRECT("$P$1:$Z$"&$M$4),COLUMN()-1,0)) | F50: =IF($M$4=0,"",VLOOKUP($B50,INDIRECT("$P$1:$Z$"&$M$4),COLUMN()-1,0)) | G50: =IF($M$4=0,"",VLOOKUP($B50,INDIRECT("$P$1:$Z$"&$M$4),COLUMN()-1,0)) | H50: =IF($M$4=0,"",VLOOKUP($B50,INDIRECT("$P$1:$Z$"&$M$4),COLUMN()-1,0)) | I50: =IF($M$4=0,"",VLOOKUP($B50,INDIRECT("$P$1:$Z$"&$M$4),COLUMN()-1,0)) | J50: =IF($M$4=0,"",VLOOKUP($B50,INDIRECT("$P$1:$Z$"&$M$4),COLUMN()-1,0)) | ... L50: =IF($M$4=0,"",VLOOKUP($B50,INDIRECT("$P$1:$Z$"&$M$4),COLUMN()-1,0))
B51: =IF(Calculation!BE57="","",Calculation!BE57) | C51: =IF($M$4=0,"",VLOOKUP($B51,INDIRECT("$P$1:$Z$"&$M$4),COLUMN()-1,0)) | D51: =IF($M$4=0,"",VLOOKUP($B51,INDIRECT("$P$1:$Z$"&$M$4),COLUMN()-1,0)) | E51: =IF($M$4=0,"",VLOOKUP($B51,INDIRECT("$P$1:$Z$"&$M$4),COLUMN()-1,0)) | F51: =IF($M$4=0,"",VLOOKUP($B51,INDIRECT("$P$1:$Z$"&$M$4),COLUMN()-1,0)) | G51: =IF($M$4=0,"",VLOOKUP($B51,INDIRECT("$P$1:$Z$"&$M$4),COLUMN()-1,0)) | H51: =IF($M$4=0,"",VLOOKUP($B51,INDIRECT("$P$1:$Z$"&$M$4),COLUMN()-1,0)) | I51: =IF($M$4=0,"",VLOOKUP($B51,INDIRECT("$P$1:$Z$"&$M$4),COLUMN()-1,0)) | J51: =IF($M$4=0,"",VLOOKUP($B51,INDIRECT("$P$1:$Z$"&$M$4),COLUMN()-1,0)) | ... L51: =IF($M$4=0,"",VLOOKUP($B51,INDIRECT("$P$1:$Z$"&$M$4),COLUMN()-1,0))
B52: =IF(Calculation!BE58="","",Calculation!BE58) | C52: =IF($M$4=0,"",VLOOKUP($B52,INDIRECT("$P$1:$Z$"&$M$4),COLUMN()-1,0)) | D52: =IF($M$4=0,"",VLOOKUP($B52,INDIRECT("$P$1:$Z$"&$M$4),COLUMN()-1,0)) | E52: =IF($M$4=0,"",VLOOKUP($B52,INDIRECT("$P$1:$Z$"&$M$4),COLUMN()-1,0)) | F52: =IF($M$4=0,"",VLOOKUP($B52,INDIRECT("$P$1:$Z$"&$M$4),COLUMN()-1,0)) | G52: =IF($M$4=0,"",VLOOKUP($B52,INDIRECT("$P$1:$Z$"&$M$4),COLUMN()-1,0)) | H52: =IF($M$4=0,"",VLOOKUP($B52,INDIRECT("$P$1:$Z$"&$M$4),COLUMN()-1,0)) | I52: =IF($M$4=0,"",VLOOKUP($B52,INDIRECT("$P$1:$Z$"&$M$4),COLUMN()-1,0)) | J52: =IF($M$4=0,"",VLOOKUP($B52,INDIRECT("$P$1:$Z$"&$M$4),COLUMN()-1,0)) | ... L52: =IF($M$4=0,"",VLOOKUP($B52,INDIRECT("$P$1:$Z$"&$M$4),COLUMN()-1,0))
... B55: =IF(Calculation!BE61="","",Calculation!BE61) | C55: =IF($M$4=0,"",VLOOKUP($B55,INDIRECT("$P$1:$Z$"&$M$4),COLUMN()-1,0)) | D55: =IF($M$4=0,"",VLOOKUP($B55,INDIRECT("$P$1:$Z$"&$M$4),COLUMN()-1,0)) | E55: =IF($M$4=0,"",VLOOKUP($B55,INDIRECT("$P$1:$Z$"&$M$4),COLUMN()-1,0)) | F55: =IF($M$4=0,"",VLOOKUP($B55,INDIRECT("$P$1:$Z$"&$M$4),COLUMN()-1,0)) | G55: =IF($M$4=0,"",VLOOKUP($B55,INDIRECT("$P$1:$Z$"&$M$4),COLUMN()-1,0)) | H55: =IF($M$4=0,"",VLOOKUP($B55,INDIRECT("$P$1:$Z$"&$M$4),COLUMN()-1,0)) | I55: =IF($M$4=0,"",VLOOKUP($B55,INDIRECT("$P$1:$Z$"&$M$4),COLUMN()-1,0)) | J55: =IF($M$4=0,"",VLOOKUP($B55,INDIRECT("$P$1:$Z$"&$M$4),COLUMN()-1,0)) | ... L55: =IF($M$4=0,"",VLOOKUP($B55,INDIRECT("$P$1:$Z$"&$M$4),COLUMN()-1,0))

Sheet Case 3
B1: ELEMENT | C1: AXIAL | D1: SHEAR | E1: BENDING | F1: TORSION | G1: -----------Forces(N. | H1: )----------- | I1: ---------Moments(N.m. | J1: )------
B2: NODES: | C2: FORCE | D2: FORCE | E2: MOMENT | F2: MOMENT | G2: FX | H2: FY | I2: FZ | J2: MX | K2: MY | L2: MZ
B4: CASE | C4: =IF(P1="","","L"&MID(INDIRECT("P"&L4),6,2)) | D4: =IF(P1="","",MID(INDIRECT("P"&L4),SEARCH("(",INDIRECT("P"&L4),1)+1,3)) | E4: =IF(P1="","",MID(INDIRECT("P"&L4),SEARCH(")",INDIRECT("P"&L4),1)+2,LEN(INDIRECT("P"&L4)))) | L4: =IF(P1="","",MATCH("CASE*",P1:P10,0)) | M4: =ROUND(COUNT(P:P)*1.6,0) -> 0
B6: =IF(Calculation!BE11="","",Calculation!BE11) | C6: =IF($M$4=0,"",VLOOKUP($B6,INDIRECT("$P$1:$Z$"&$M$4),COLUMN()-1,0)) | D6: =IF($M$4=0,"",VLOOKUP($B6,INDIRECT("$P$1:$Z$"&$M$4),COLUMN()-1,0)) | E6: =IF($M$4=0,"",VLOOKUP($B6,INDIRECT("$P$1:$Z$"&$M$4),COLUMN()-1,0)) | F6: =IF($M$4=0,"",VLOOKUP($B6,INDIRECT("$P$1:$Z$"&$M$4),COLUMN()-1,0)) | G6: =IF($M$4=0,"",VLOOKUP($B6,INDIRECT("$P$1:$Z$"&$M$4),COLUMN()-1,0)) | H6: =IF($M$4=0,"",VLOOKUP($B6,INDIRECT("$P$1:$Z$"&$M$4),COLUMN()-1,0)) | I6: =IF($M$4=0,"",VLOOKUP($B6,INDIRECT("$P$1:$Z$"&$M$4),COLUMN()-1,0)) | J6: =IF($M$4=0,"",VLOOKUP($B6,INDIRECT("$P$1:$Z$"&$M$4),COLUMN()-1,0)) | ... L6: =IF($M$4=0,"",VLOOKUP($B6,INDIRECT("$P$1:$Z$"&$M$4),COLUMN()-1,0))
B7: =IF(Calculation!BE12="","",Calculation!BE12) | C7: =IF($M$4=0,"",VLOOKUP($B7,INDIRECT("$P$1:$Z$"&$M$4),COLUMN()-1,0)) | D7: =IF($M$4=0,"",VLOOKUP($B7,INDIRECT("$P$1:$Z$"&$M$4),COLUMN()-1,0)) | E7: =IF($M$4=0,"",VLOOKUP($B7,INDIRECT("$P$1:$Z$"&$M$4),COLUMN()-1,0)) | F7: =IF($M$4=0,"",VLOOKUP($B7,INDIRECT("$P$1:$Z$"&$M$4),COLUMN()-1,0)) | G7: =IF($M$4=0,"",VLOOKUP($B7,INDIRECT("$P$1:$Z$"&$M$4),COLUMN()-1,0)) | H7: =IF($M$4=0,"",VLOOKUP($B7,INDIRECT("$P$1:$Z$"&$M$4),COLUMN()-1,0)) | I7: =IF($M$4=0,"",VLOOKUP($B7,INDIRECT("$P$1:$Z$"&$M$4),COLUMN()-1,0)) | J7: =IF($M$4=0,"",VLOOKUP($B7,INDIRECT("$P$1:$Z$"&$M$4),COLUMN()-1,0)) | ... L7: =IF($M$4=0,"",VLOOKUP($B7,INDIRECT("$P$1:$Z$"&$M$4),COLUMN()-1,0))
B8: =IF(Calculation!BE13="","",Calculation!BE13) | C8: =IF($M$4=0,"",VLOOKUP($B8,INDIRECT("$P$1:$Z$"&$M$4),COLUMN()-1,0)) | D8: =IF($M$4=0,"",VLOOKUP($B8,INDIRECT("$P$1:$Z$"&$M$4),COLUMN()-1,0)) | E8: =IF($M$4=0,"",VLOOKUP($B8,INDIRECT("$P$1:$Z$"&$M$4),COLUMN()-1,0)) | F8: =IF($M$4=0,"",VLOOKUP($B8,INDIRECT("$P$1:$Z$"&$M$4),COLUMN()-1,0)) | G8: =IF($M$4=0,"",VLOOKUP($B8,INDIRECT("$P$1:$Z$"&$M$4),COLUMN()-1,0)) | H8: =IF($M$4=0,"",VLOOKUP($B8,INDIRECT("$P$1:$Z$"&$M$4),COLUMN()-1,0)) | I8: =IF($M$4=0,"",VLOOKUP($B8,INDIRECT("$P$1:$Z$"&$M$4),COLUMN()-1,0)) | J8: =IF($M$4=0,"",VLOOKUP($B8,INDIRECT("$P$1:$Z$"&$M$4),COLUMN()-1,0)) | ... L8: =IF($M$4=0,"",VLOOKUP($B8,INDIRECT("$P$1:$Z$"&$M$4),COLUMN()-1,0))
B9: =IF(Calculation!BE14="","",Calculation!BE14) | C9: =IF($M$4=0,"",VLOOKUP($B9,INDIRECT("$P$1:$Z$"&$M$4),COLUMN()-1,0)) | D9: =IF($M$4=0,"",VLOOKUP($B9,INDIRECT("$P$1:$Z$"&$M$4),COLUMN()-1,0)) | E9: =IF($M$4=0,"",VLOOKUP($B9,INDIRECT("$P$1:$Z$"&$M$4),COLUMN()-1,0)) | F9: =IF($M$4=0,"",VLOOKUP($B9,INDIRECT("$P$1:$Z$"&$M$4),COLUMN()-1,0)) | G9: =IF($M$4=0,"",VLOOKUP($B9,INDIRECT("$P$1:$Z$"&$M$4),COLUMN()-1,0)) | H9: =IF($M$4=0,"",VLOOKUP($B9,INDIRECT("$P$1:$Z$"&$M$4),COLUMN()-1,0)) | I9: =IF($M$4=0,"",VLOOKUP($B9,INDIRECT("$P$1:$Z$"&$M$4),COLUMN()-1,0)) | J9: =IF($M$4=0,"",VLOOKUP($B9,INDIRECT("$P$1:$Z$"&$M$4),COLUMN()-1,0)) | ... L9: =IF($M$4=0,"",VLOOKUP($B9,INDIRECT("$P$1:$Z$"&$M$4),COLUMN()-1,0))
B10: =IF(Calculation!BE15="","",Calculation!BE15) | C10: =IF($M$4=0,"",VLOOKUP($B10,INDIRECT("$P$1:$Z$"&$M$4),COLUMN()-1,0)) | D10: =IF($M$4=0,"",VLOOKUP($B10,INDIRECT("$P$1:$Z$"&$M$4),COLUMN()-1,0)) | E10: =IF($M$4=0,"",VLOOKUP($B10,INDIRECT("$P$1:$Z$"&$M$4),COLUMN()-1,0)) | F10: =IF($M$4=0,"",VLOOKUP($B10,INDIRECT("$P$1:$Z$"&$M$4),COLUMN()-1,0)) | G10: =IF($M$4=0,"",VLOOKUP($B10,INDIRECT("$P$1:$Z$"&$M$4),COLUMN()-1,0)) | H10: =IF($M$4=0,"",VLOOKUP($B10,INDIRECT("$P$1:$Z$"&$M$4),COLUMN()-1,0)) | I10: =IF($M$4=0,"",VLOOKUP($B10,INDIRECT("$P$1:$Z$"&$M$4),COLUMN()-1,0)) | J10: =IF($M$4=0,"",VLOOKUP($B10,INDIRECT("$P$1:$Z$"&$M$4),COLUMN()-1,0)) | ... L10: =IF($M$4=0,"",VLOOKUP($B10,INDIRECT("$P$1:$Z$"&$M$4),COLUMN()-1,0))
B11: =IF(Calculation!BE16="","",Calculation!BE16) | C11: =IF($M$4=0,"",VLOOKUP($B11,INDIRECT("$P$1:$Z$"&$M$4),COLUMN()-1,0)) | D11: =IF($M$4=0,"",VLOOKUP($B11,INDIRECT("$P$1:$Z$"&$M$4),COLUMN()-1,0)) | E11: =IF($M$4=0,"",VLOOKUP($B11,INDIRECT("$P$1:$Z$"&$M$4),COLUMN()-1,0)) | F11: =IF($M$4=0,"",VLOOKUP($B11,INDIRECT("$P$1:$Z$"&$M$4),COLUMN()-1,0)) | G11: =IF($M$4=0,"",VLOOKUP($B11,INDIRECT("$P$1:$Z$"&$M$4),COLUMN()-1,0)) | H11: =IF($M$4=0,"",VLOOKUP($B11,INDIRECT("$P$1:$Z$"&$M$4),COLUMN()-1,0)) | I11: =IF($M$4=0,"",VLOOKUP($B11,INDIRECT("$P$1:$Z$"&$M$4),COLUMN()-1,0)) | J11: =IF($M$4=0,"",VLOOKUP($B11,INDIRECT("$P$1:$Z$"&$M$4),COLUMN()-1,0)) | ... L11: =IF($M$4=0,"",VLOOKUP($B11,INDIRECT("$P$1:$Z$"&$M$4),COLUMN()-1,0))
B12: =IF(Calculation!BE17="","",Calculation!BE17) | C12: =IF($M$4=0,"",VLOOKUP($B12,INDIRECT("$P$1:$Z$"&$M$4),COLUMN()-1,0)) | D12: =IF($M$4=0,"",VLOOKUP($B12,INDIRECT("$P$1:$Z$"&$M$4),COLUMN()-1,0)) | E12: =IF($M$4=0,"",VLOOKUP($B12,INDIRECT("$P$1:$Z$"&$M$4),COLUMN()-1,0)) | F12: =IF($M$4=0,"",VLOOKUP($B12,INDIRECT("$P$1:$Z$"&$M$4),COLUMN()-1,0)) | G12: =IF($M$4=0,"",VLOOKUP($B12,INDIRECT("$P$1:$Z$"&$M$4),COLUMN()-1,0)) | H12: =IF($M$4=0,"",VLOOKUP($B12,INDIRECT("$P$1:$Z$"&$M$4),COLUMN()-1,0)) | I12: =IF($M$4=0,"",VLOOKUP($B12,INDIRECT("$P$1:$Z$"&$M$4),COLUMN()-1,0)) | J12: =IF($M$4=0,"",VLOOKUP($B12,INDIRECT("$P$1:$Z$"&$M$4),COLUMN()-1,0)) | ... L12: =IF($M$4=0,"",VLOOKUP($B12,INDIRECT("$P$1:$Z$"&$M$4),COLUMN()-1,0))
B13: =IF(Calculation!BE18="","",Calculation!BE18) | C13: =IF($M$4=0,"",VLOOKUP($B13,INDIRECT("$P$1:$Z$"&$M$4),COLUMN()-1,0)) | D13: =IF($M$4=0,"",VLOOKUP($B13,INDIRECT("$P$1:$Z$"&$M$4),COLUMN()-1,0)) | E13: =IF($M$4=0,"",VLOOKUP($B13,INDIRECT("$P$1:$Z$"&$M$4),COLUMN()-1,0)) | F13: =IF($M$4=0,"",VLOOKUP($B13,INDIRECT("$P$1:$Z$"&$M$4),COLUMN()-1,0)) | G13: =IF($M$4=0,"",VLOOKUP($B13,INDIRECT("$P$1:$Z$"&$M$4),COLUMN()-1,0)) | H13: =IF($M$4=0,"",VLOOKUP($B13,INDIRECT("$P$1:$Z$"&$M$4),COLUMN()-1,0)) | I13: =IF($M$4=0,"",VLOOKUP($B13,INDIRECT("$P$1:$Z$"&$M$4),COLUMN()-1,0)) | J13: =IF($M$4=0,"",VLOOKUP($B13,INDIRECT("$P$1:$Z$"&$M$4),COLUMN()-1,0)) | ... L13: =IF($M$4=0,"",VLOOKUP($B13,INDIRECT("$P$1:$Z$"&$M$4),COLUMN()-1,0))
B14: =IF(Calculation!BE19="","",Calculation!BE19) | C14: =IF($M$4=0,"",VLOOKUP($B14,INDIRECT("$P$1:$Z$"&$M$4),COLUMN()-1,0)) | D14: =IF($M$4=0,"",VLOOKUP($B14,INDIRECT("$P$1:$Z$"&$M$4),COLUMN()-1,0)) | E14: =IF($M$4=0,"",VLOOKUP($B14,INDIRECT("$P$1:$Z$"&$M$4),COLUMN()-1,0)) | F14: =IF($M$4=0,"",VLOOKUP($B14,INDIRECT("$P$1:$Z$"&$M$4),COLUMN()-1,0)) | G14: =IF($M$4=0,"",VLOOKUP($B14,INDIRECT("$P$1:$Z$"&$M$4),COLUMN()-1,0)) | H14: =IF($M$4=0,"",VLOOKUP($B14,INDIRECT("$P$1:$Z$"&$M$4),COLUMN()-1,0)) | I14: =IF($M$4=0,"",VLOOKUP($B14,INDIRECT("$P$1:$Z$"&$M$4),COLUMN()-1,0)) | J14: =IF($M$4=0,"",VLOOKUP($B14,INDIRECT("$P$1:$Z$"&$M$4),COLUMN()-1,0)) | ... L14: =IF($M$4=0,"",VLOOKUP($B14,INDIRECT("$P$1:$Z$"&$M$4),COLUMN()-1,0))
B15: =IF(Calculation!BE20="","",Calculation!BE20) | C15: =IF($M$4=0,"",VLOOKUP($B15,INDIRECT("$P$1:$Z$"&$M$4),COLUMN()-1,0)) | D15: =IF($M$4=0,"",VLOOKUP($B15,INDIRECT("$P$1:$Z$"&$M$4),COLUMN()-1,0)) | E15: =IF($M$4=0,"",VLOOKUP($B15,INDIRECT("$P$1:$Z$"&$M$4),COLUMN()-1,0)) | F15: =IF($M$4=0,"",VLOOKUP($B15,INDIRECT("$P$1:$Z$"&$M$4),COLUMN()-1,0)) | G15: =IF($M$4=0,"",VLOOKUP($B15,INDIRECT("$P$1:$Z$"&$M$4),COLUMN()-1,0)) | H15: =IF($M$4=0,"",VLOOKUP($B15,INDIRECT("$P$1:$Z$"&$M$4),COLUMN()-1,0)) | I15: =IF($M$4=0,"",VLOOKUP($B15,INDIRECT("$P$1:$Z$"&$M$4),COLUMN()-1,0)) | J15: =IF($M$4=0,"",VLOOKUP($B15,INDIRECT("$P$1:$Z$"&$M$4),COLUMN()-1,0)) | ... L15: =IF($M$4=0,"",VLOOKUP($B15,INDIRECT("$P$1:$Z$"&$M$4),COLUMN()-1,0))
B16: =IF(Calculation!BE21="","",Calculation!BE21) | C16: =IF($M$4=0,"",VLOOKUP($B16,INDIRECT("$P$1:$Z$"&$M$4),COLUMN()-1,0)) | D16: =IF($M$4=0,"",VLOOKUP($B16,INDIRECT("$P$1:$Z$"&$M$4),COLUMN()-1,0)) | E16: =IF($M$4=0,"",VLOOKUP($B16,INDIRECT("$P$1:$Z$"&$M$4),COLUMN()-1,0)) | F16: =IF($M$4=0,"",VLOOKUP($B16,INDIRECT("$P$1:$Z$"&$M$4),COLUMN()-1,0)) | G16: =IF($M$4=0,"",VLOOKUP($B16,INDIRECT("$P$1:$Z$"&$M$4),COLUMN()-1,0)) | H16: =IF($M$4=0,"",VLOOKUP($B16,INDIRECT("$P$1:$Z$"&$M$4),COLUMN()-1,0)) | I16: =IF($M$4=0,"",VLOOKUP($B16,INDIRECT("$P$1:$Z$"&$M$4),COLUMN()-1,0)) | J16: =IF($M$4=0,"",VLOOKUP($B16,INDIRECT("$P$1:$Z$"&$M$4),COLUMN()-1,0)) | ... L16: =IF($M$4=0,"",VLOOKUP($B16,INDIRECT("$P$1:$Z$"&$M$4),COLUMN()-1,0))
B17: =IF(Calculation!BE22="","",Calculation!BE22) | C17: =IF($M$4=0,"",VLOOKUP($B17,INDIRECT("$P$1:$Z$"&$M$4),COLUMN()-1,0)) | D17: =IF($M$4=0,"",VLOOKUP($B17,INDIRECT("$P$1:$Z$"&$M$4),COLUMN()-1,0)) | E17: =IF($M$4=0,"",VLOOKUP($B17,INDIRECT("$P$1:$Z$"&$M$4),COLUMN()-1,0)) | F17: =IF($M$4=0,"",VLOOKUP($B17,INDIRECT("$P$1:$Z$"&$M$4),COLUMN()-1,0)) | G17: =IF($M$4=0,"",VLOOKUP($B17,INDIRECT("$P$1:$Z$"&$M$4),COLUMN()-1,0)) | H17: =IF($M$4=0,"",VLOOKUP($B17,INDIRECT("$P$1:$Z$"&$M$4),COLUMN()-1,0)) | I17: =IF($M$4=0,"",VLOOKUP($B17,INDIRECT("$P$1:$Z$"&$M$4),COLUMN()-1,0)) | J17: =IF($M$4=0,"",VLOOKUP($B17,INDIRECT("$P$1:$Z$"&$M$4),COLUMN()-1,0)) | ... L17: =IF($M$4=0,"",VLOOKUP($B17,INDIRECT("$P$1:$Z$"&$M$4),COLUMN()-1,0))
